Workbook

Sheet Liverpool vs Path Comms
A1: FactorType | B1: FactorName | C1: NodeColor | D1: =VLOOKUP(C1,CATA!A:B,2,FALSE) -> HexColor | E1: Attribute | F1: HexColorAtt | G1: Orden | I1: Path = Right
A2: Path | B2: Facilidad flexibilidad y ágil | C2: Kantar Orange | D2: =_xlfn.IFNA(VLOOKUP(C2,Table1[],2,FALSE),"") -> #FF5000 | E2: Acepta devoluciones fácilmente | F2: #FF5000 | G2: 41 | I2: Tracking = Left
A3: Path | B3: Facilidad flexibilidad y ágil | C3: Kantar Orange | D3: =_xlfn.IFNA(VLOOKUP(C3,Table1[],2,FALSE),"") -> #FF5000 | E3: Cuenta con la mejor tarjeta de crédito | F3: #FF5000 | G3: 59 | L3: Confianza & Cercanía
A4: Path | B4: Servicio de calidad en tienda física | C4: Kantar Yellow | D4: =_xlfn.IFNA(VLOOKUP(C4,Table1[],2,FALSE),"") -> #FEDB00 | E4: El personal me apoya a comparar en línea si el producto no está | F4: #FEDB00 | G4: 52 | L4: Confianza & Cercanía
A5: Path | B5: Servicio de calidad en tienda física | C5: Kantar Yellow | D5: =_xlfn.IFNA(VLOOKUP(C5,Table1[],2,FALSE),"") -> #FEDB00 | E5: El personal resuelve problemas y dudas | F5: #FEDB00 | G5: 38 | L5: Confianza & Cercanía
A6: Path | B6: Confianza, calidad y vanguardia | C6: Kantar Purple | D6: =_xlfn.IFNA(VLOOKUP(C6,Table1[],2,FALSE),"") -> #802AB7 | E6: Encuentra variedad de tallas | F6: #802AB7 | G6: 34 | L6: Confianza & Cercanía
A7: Path | B7: Conexión emocional | C7: Kantar Teal | D7: =_xlfn.IFNA(VLOOKUP(C7,Table1[],2,FALSE),"") -> #00E5BA | E7: Es un lugar donde encuentro todo lo que necesito y/o busco | F7: #00E5BA | G7: 48 | L7: Confianza & Cercanía
A8: Path | B8: Servicio de calidad en tienda física | C8: Kantar Yellow | D8: =_xlfn.IFNA(VLOOKUP(C8,Table1[],2,FALSE),"") -> #FEDB00 | E8: Es un lugar donde le atienden rápido | F8: #FEDB00 | G8: 37 | L8: Confianza & Cercanía | M8: Es una tienda que me invita a visitarla
A9: Path | B9: Estatus vigente y renovado | C9: Kantar Blue | D9: =_xlfn.IFNA(VLOOKUP(C9,Table1[],2,FALSE),"") -> #0060FF | E9: Es una marca actual y vigente | F9: #0060FF | G9: 57 | L9: Confianza & Cercanía
A10: Path | B10: Confianza, calidad y vanguardia | C10: Kantar Purple | D10: =_xlfn.IFNA(VLOOKUP(C10,Table1[],2,FALSE),"") -> #802AB7 | E10: Es una marca que me transmite confianza tanto en tienda como en línea | F10: #802AB7 | G10: 49 | L10: Conexión Emocional
A11: Path | B11: Medio Ambiente | C11: Kantar Light Grey | D11: =_xlfn.IFNA(VLOOKUP(C11,Table1[],2,FALSE),"") -> #D9D9D9 | E11: Es una marca que se preocupa por el medio ambiente | F11: #D9D9D9 | G11: 43 | L11: Conexión Emocional
A12: Path | B12: Confianza, calidad y vanguardia | C12: Kantar Purple | D12: =_xlfn.IFNA(VLOOKUP(C12,Table1[],2,FALSE),"") -> #802AB7 | E12: Es una tienda autorizada y respaldada por marcas de calidad | F12: #802AB7 | G12: 51 | L12: Conexión Emocional
A13: Path | B13: Confianza, calidad y vanguardia | C13: Kantar Purple | D13: =_xlfn.IFNA(VLOOKUP(C13,Table1[],2,FALSE),"") -> #802AB7 | E13: Es una tienda innovadora | F13: #802AB7 | G13: 32 | L13: Conveniente
A14: Path | B14: Conexión emocional | C14: Kantar Teal | D14: =_xlfn.IFNA(VLOOKUP(C14,Table1[],2,FALSE),"") -> #00E5BA | E14: Es una tienda para mí / con la que me identifico | F14: #00E5BA | G14: 60 | L14: Conveniente
A15: Path | B15: Conexión emocional | C15: Kantar Teal | D15: =_xlfn.IFNA(VLOOKUP(C15,Table1[],2,FALSE),"") -> #00E5BA | E15: Hace posible que viva mejor cada día | F15: #00E5BA | G15: 62 | L15: Conveniente
A16: Path | B16: Conveniencia online | C16: Kantar Green | D16: =_xlfn.IFNA(VLOOKUP(C16,Table1[],2,FALSE),"") -> #00B600 | E16: La tienda online tiene reseñas reales que la hacen confiable | F16: #00B600 | G16: 36 | L16: Conveniente
A17: Path | B17: Estatus vigente y renovado | C17: Kantar Blue | D17: =_xlfn.IFNA(VLOOKUP(C17,Table1[],2,FALSE),"") -> #0060FF | E17: Me ayuda a reflejar mi éxito | F17: #0060FF | G17: 56 | L17: Conveniente
A18: Path | B18: Estatus vigente y renovado | C18: Kantar Blue | D18: =_xlfn.IFNA(VLOOKUP(C18,Table1[],2,FALSE),"") -> #0060FF | E18: Me da mayor estatus social | F18: #0060FF | G18: 40 | L18: Facilidad & Flexibilidad
A19: Path | B19: Conexión emocional | C19: Kantar Teal | D19: =_xlfn.IFNA(VLOOKUP(C19,Table1[],2,FALSE),"") -> #00E5BA | E19: Me ha acompañado a lo largo de mi vida | F19: #00E5BA | G19: 61 | L19: Facilidad & Flexibilidad
A20: Path | B20: Conveniencia online | C20: Kantar Green | D20: =_xlfn.IFNA(VLOOKUP(C20,Table1[],2,FALSE),"") -> #00B600 | E20: Ofrece las mejores garantías | F20: #00B600 | G20: 39 | L20: Practicidad
A21: Path | B21: Servicio de calidad en tienda física | C21: Kantar Yellow | D21: =_xlfn.IFNA(VLOOKUP(C21,Table1[],2,FALSE),"") -> #FEDB00 | E21: Ofrece un servicio cálido, cercano, respetuoso y atento | F21: #FEDB00 | G21: 54 | L21: Practicidad | M21: Me permite hacer compras de manera práctica y cómoda
A22: Path | B22: Precios | C22: Kantar Red | D22: =_xlfn.IFNA(VLOOKUP(C22,Table1[],2,FALSE),"") -> #FA0028 | E22: Ropa/calzado y accesorios valen el precio que se paga | F22: #FA0028 | G22: 44 | L22: Practicidad
A23: Path | B23: Conveniencia online | C23: Kantar Green | D23: =_xlfn.IFNA(VLOOKUP(C23,Table1[],2,FALSE),"") -> #00B600 | E23: Su página web / app es segura, fácil y sencilla de navegar | F23: #00B600 | G23: 46 | L23: Estatus Renovado
A24: Path | B24: Estatus vigente y renovado | C24: Kantar Blue | D24: =_xlfn.IFNA(VLOOKUP(C24,Table1[],2,FALSE),"") -> #0060FF | E24: Su publicidad me dice algo relevante de la marca | F24: #0060FF | G24: 58 | L24: Estatus Renovado | M24: En su última campaña, la marca transmite una sensación de renovación
A25: Path | B25: Conveniencia online | C25: Kantar Green | D25: =_xlfn.IFNA(VLOOKUP(C25,Table1[],2,FALSE),"") -> #00B600 | E25: Su sitio online tiene las mejores descripciones de productos | F25: #00B600 | G25: 47
A26: Path | B26: Precios | C26: Kantar Red | D26: =_xlfn.IFNA(VLOOKUP(C26,Table1[],2,FALSE),"") -> #FA0028 | E26: Tiene las mejores promociones | F26: #FA0028 | G26: 53
A27: Path | B27: Confianza, calidad y vanguardia | C27: Kantar Purple | D27: =_xlfn.IFNA(VLOOKUP(C27,Table1[],2,FALSE),"") -> #802AB7 | E27: Tiene las opciones de pago adecuadas (crédito, efectivo, pagos digitales) | F27: #802AB7 | G27: 35
A28: Path | B28: Confianza, calidad y vanguardia | C28: Kantar Purple | D28: =_xlfn.IFNA(VLOOKUP(C28,Table1[],2,FALSE),"") -> #802AB7 | E28: Tiene lo último de la moda | F28: #802AB7 | G28: 33
A29: Path | B29: Precios | C29: Kantar Red | D29: =_xlfn.IFNA(VLOOKUP(C29,Table1[],2,FALSE),"") -> #FA0028 | E29: Tiene los mejores precios | F29: #FA0028 | G29: 45
A30: Path | B30: Facilidad flexibilidad y ágil | C30: Kantar Orange | D30: =_xlfn.IFNA(VLOOKUP(C30,Table1[],2,FALSE),"") -> #FF5000 | E30: Tiene los mejores tiempos de entrega | F30: #FF5000 | G30: 42
A31: Path | B31: Servicio de calidad en tienda física | C31: Kantar Yellow | D31: =_xlfn.IFNA(VLOOKUP(C31,Table1[],2,FALSE),"") -> #FEDB00 | E31: Tiene un ambiente e instalaciones agradables | F31: #FEDB00 | G31: 55
A32: Path | B32: Confianza, calidad y vanguardia | C32: Kantar Purple | D32: =_xlfn.IFNA(VLOOKUP(C32,Table1[],2,FALSE),"") -> #802AB7 | E32: Tiene una amplia variedad de productos de calidad | F32: #802AB7 | G32: 50
A33: Tracking | B33: Facilidad y Flexibilidad | C33: Kantar Yellow | D33: =_xlfn.IFNA(VLOOKUP(C33,Table1[],2,FALSE),"") -> #FEDB00 | E33: Acepta devoluciones fácilmente | F33: #FF5000 | G33: 15
A34: Tracking | B34: Facilidad y Flexibilidad | C34: Kantar Yellow | D34: =_xlfn.IFNA(VLOOKUP(C34,Table1[],2,FALSE),"") -> #FEDB00 | E34: Cuenta con la mejor tarjeta de crédito | F34: #FF5000 | G34: 14
A35: Tracking | B35: NA | C35: Kantar Sand | D35: =_xlfn.IFNA(VLOOKUP(C35,Table1[],2,FALSE),"") -> #AEAE9F | E35: El personal me apoya a comparar en línea si el producto no está | F35: #FEDB00 | G35: 28
A36: Tracking | B36: NA | C36: Kantar Sand | D36: =_xlfn.IFNA(VLOOKUP(C36,Table1[],2,FALSE),"") -> #AEAE9F | E36: El personal resuelve problemas y dudas | F36: #FEDB00 | G36: 13
... A63: Tracking | B63: Confianza y cercanía | C63: Kantar Purple | D63: =_xlfn.IFNA(VLOOKUP(C63,Table1[],2,FALSE),"") -> #802AB7 | E63: Tiene una amplia variedad de productos de calidad | F63: #802AB7 | G63: 8

Sheet Liverpool vs Cat
A1: FactorType | B1: FactorName | C1: NodeColor | D1: =VLOOKUP(C1,CATA!A:B,2,FALSE) -> HexColor | E1: Attribute | F1: Orden | H1: Path = Right
A2: Path | B2: Conexión emocional | C2: Kantar Teal | D2: =_xlfn.IFNA(VLOOKUP(C2,Table1[],2,FALSE),"") -> #00E5BA | E2: Es una tienda para mí / con la que me identifico | F2: 32 | H2: Tracking = Left
A3: Path | B3: Conexión emocional | C3: Kantar Teal | D3: =_xlfn.IFNA(VLOOKUP(C3,Table1[],2,FALSE),"") -> #00E5BA | E3: Me ha acompañado a lo largo de mi vida | F3: 33
A4: Path | B4: Conexión emocional | C4: Kantar Teal | D4: =_xlfn.IFNA(VLOOKUP(C4,Table1[],2,FALSE),"") -> #00E5BA | E4: Hace posible que viva mejor cada día | F4: 34
A5: Path | B5: Conexión emocional | C5: Kantar Teal | D5: =_xlfn.IFNA(VLOOKUP(C5,Table1[],2,FALSE),"") -> #00E5BA | E5: Es un lugar donde encuentro todo lo que necesito y/o busco | F5: 35
A6: Path | B6: Confianza, calidad y vanguardia | C6: Kantar Purple | D6: =_xlfn.IFNA(VLOOKUP(C6,Table1[],2,FALSE),"") -> #802AB7 | E6: Es una marca que me transmite confianza tanto en tienda como en línea | F6: 36
A7: Path | B7: Confianza, calidad y vanguardia | C7: Kantar Purple | D7: =_xlfn.IFNA(VLOOKUP(C7,Table1[],2,FALSE),"") -> #802AB7 | E7: Tiene una amplia variedad de productos de calidad | F7: 37
A8: Path | B8: Confianza, calidad y vanguardia | C8: Kantar Purple | D8: =_xlfn.IFNA(VLOOKUP(C8,Table1[],2,FALSE),"") -> #802AB7 | E8: Es una tienda autorizada y respaldada por marcas de calidad | F8: 38
A9: Path | B9: Confianza, calidad y vanguardia | C9: Kantar Purple | D9: =_xlfn.IFNA(VLOOKUP(C9,Table1[],2,FALSE),"") -> #802AB7 | E9: Es una tienda innovadora | F9: 39
A10: Path | B10: Confianza, calidad y vanguardia | C10: Kantar Purple | D10: =_xlfn.IFNA(VLOOKUP(C10,Table1[],2,FALSE),"") -> #802AB7 | E10: Tiene lo último de la moda | F10: 40 | I10: Emocional | J10: Es una tienda para mí / con la que me identifico
A11: Path | B11: Confianza, calidad y vanguardia | C11: Kantar Purple | D11: =_xlfn.IFNA(VLOOKUP(C11,Table1[],2,FALSE),"") -> #802AB7 | E11: Encuentra variedad de tallas | F11: 41 | I11: Emocional | J11: Hace posible que viva mejor cada día
A12: Path | B12: Confianza, calidad y vanguardia | C12: Kantar Purple | D12: =_xlfn.IFNA(VLOOKUP(C12,Table1[],2,FALSE),"") -> #802AB7 | E12: Tiene las opciones de pago adecuadas (crédito, efectivo, pagos digitales) | F12: 42 | I12: Emocional | J12: Me ha acompañado a lo largo de mi vida
A13: Path | B13: Conveniencia online | C13: Kantar Green | D13: =_xlfn.IFNA(VLOOKUP(C13,Table1[],2,FALSE),"") -> #00B600 | E13: La tienda online tiene reseñas de otros clientes, con calificaciones e imágenes reales que la hacen confiable | F13: 43 | I13: Emocional | J13: Es una marca que me transmite confianza tanto en tienda como en línea
A14: Path | B14: Conveniencia online | C14: Kantar Green | D14: =_xlfn.IFNA(VLOOKUP(C14,Table1[],2,FALSE),"") -> #00B600 | E14: Su página web / app es segura, fácil y sencilla de navegar | F14: 44 | I14: Emocional | J14: Ofrece un servicio cálido, cercano, respetuoso y atento
A15: Path | B15: Conveniencia online | C15: Kantar Green | D15: =_xlfn.IFNA(VLOOKUP(C15,Table1[],2,FALSE),"") -> #00B600 | E15: Su sitio online tiene las mejores descripciones de productos | F15: 45 | I15: Emocional | J15: Me ayuda a reflejar mi éxito
A16: Path | B16: Conveniencia online | C16: Kantar Green | D16: =_xlfn.IFNA(VLOOKUP(C16,Table1[],2,FALSE),"") -> #00B600 | E16: Ofrece las mejores garantías | F16: 46 | I16: Emocional | J16: Es una marca que se preocupa por el medio ambiente
A17: Path | B17: Estatus vigente y renovado | C17: Kantar Blue | D17: =_xlfn.IFNA(VLOOKUP(C17,Table1[],2,FALSE),"") -> #0060FF | E17: Me da mayor estatus social | F17: 47 | I17: Emocional | J17: Tiene un ambiente e instalaciones agradables
A18: Path | B18: Estatus vigente y renovado | C18: Kantar Blue | D18: =_xlfn.IFNA(VLOOKUP(C18,Table1[],2,FALSE),"") -> #0060FF | E18: Me ayuda a reflejar mi éxito | F18: 48 | I18: Emocional | J18: Me da mayor estatus social
A19: Path | B19: Estatus vigente y renovado | C19: Kantar Blue | D19: =_xlfn.IFNA(VLOOKUP(C19,Table1[],2,FALSE),"") -> #0060FF | E19: Es una marca actual y vigente | F19: 49
A20: Path | B20: Estatus vigente y renovado | C20: Kantar Blue | D20: =_xlfn.IFNA(VLOOKUP(C20,Table1[],2,FALSE),"") -> #0060FF | E20: Su publicidad me dice algo relevante de la marca | F20: 50 | I20: Funcional | J20: Es un lugar donde encuentro todo lo que necesito y/o busco
A21: Path | B21: Facilidad flexibilidad y ágil | C21: Kantar Orange | D21: =_xlfn.IFNA(VLOOKUP(C21,Table1[],2,FALSE),"") -> #FF5000 | E21: Cuenta con la mejor tarjeta de crédito | F21: 51 | I21: Funcional | J21: Tiene una amplia variedad de productos de calidad
A22: Path | B22: Facilidad flexibilidad y ágil | C22: Kantar Orange | D22: =_xlfn.IFNA(VLOOKUP(C22,Table1[],2,FALSE),"") -> #FF5000 | E22: Acepta devoluciones fácilmente | F22: 52 | I22: Funcional | J22: Es una marca actual y vigente
A23: Path | B23: Facilidad flexibilidad y ágil | C23: Kantar Orange | D23: =_xlfn.IFNA(VLOOKUP(C23,Table1[],2,FALSE),"") -> #FF5000 | E23: Tiene los mejores tiempos de entrega | F23: 53 | I23: Funcional | J23: Su publicidad me dice algo relevante de la marca
A24: Path | B24: Medio Ambiente | C24: Kantar Light Grey | D24: =_xlfn.IFNA(VLOOKUP(C24,Table1[],2,FALSE),"") -> #D9D9D9 | E24: Es una marca que se preocupa por el medio ambiente | F24: 54 | I24: Funcional | J24: Es una tienda autorizada y respaldada por marcas de calidad
A25: Path | B25: Precios | C25: Kantar Red | D25: =_xlfn.IFNA(VLOOKUP(C25,Table1[],2,FALSE),"") -> #FA0028 | E25: Ropa/calzado y accesorios valen el precio que se paga | F25: 55 | I25: Funcional | J25: Es una tienda innovadora
A26: Path | B26: Precios | C26: Kantar Red | D26: =_xlfn.IFNA(VLOOKUP(C26,Table1[],2,FALSE),"") -> #FA0028 | E26: Tiene los mejores precios | F26: 56 | I26: Funcional | J26: Encuentra variedad de tallas
A27: Path | B27: Precios | C27: Kantar Red | D27: =_xlfn.IFNA(VLOOKUP(C27,Table1[],2,FALSE),"") -> #FA0028 | E27: Tiene las mejores promociones | F27: 57 | I27: Funcional | J27: Cuenta con la mejor tarjeta de crédito
A28: Path | B28: Servicio de calidad en tienda física | C28: Kantar Yellow | D28: =_xlfn.IFNA(VLOOKUP(C28,Table1[],2,FALSE),"") -> #FEDB00 | E28: Ofrece un servicio cálido, cercano, respetuoso y atento | F28: 58 | I28: Funcional | J28: Tiene lo último de la moda
A29: Path | B29: Servicio de calidad en tienda física | C29: Kantar Yellow | D29: =_xlfn.IFNA(VLOOKUP(C29,Table1[],2,FALSE),"") -> #FEDB00 | E29: Tiene un ambiente e instalaciones agradables | F29: 59
A30: Path | B30: Servicio de calidad en tienda física | C30: Kantar Yellow | D30: =_xlfn.IFNA(VLOOKUP(C30,Table1[],2,FALSE),"") -> #FEDB00 | E30: Es un lugar donde le atienden rápido | F30: 60 | I30: Digital | J30: Su página web / app es segura, fácil y sencilla de navegar
A31: Path | B31: Servicio de calidad en tienda física | C31: Kantar Yellow | D31: =_xlfn.IFNA(VLOOKUP(C31,Table1[],2,FALSE),"") -> #FEDB00 | E31: El personal resuelve problemas y dudas | F31: 61 | I31: Digital | J31: Su sitio online tiene las mejores descripciones de productos
A32: Path | B32: Servicio de calidad en tienda física | C32: Kantar Yellow | D32: =_xlfn.IFNA(VLOOKUP(C32,Table1[],2,FALSE),"") -> #FEDB00 | E32: El personal me apoya a comparar en línea si el producto no está disponible en tienda | F32: 62 | I32: Digital | J32: La tienda online tiene reseñas de otros clientes, con calificaciones e imágenes reales que la hacen confiable
A33: Tracking | B33: Digital | C33: Kantar Green | D33: =_xlfn.IFNA(VLOOKUP(C33,Table1[],2,FALSE),"") -> #00B600 | E33: La tienda online tiene reseñas de otros clientes, con calificaciones e imágenes reales que la hacen confiable | F33: 12
A34: Tracking | B34: Digital | C34: Kantar Green | D34: =_xlfn.IFNA(VLOOKUP(C34,Table1[],2,FALSE),"") -> #00B600 | E34: Su página web / app es segura, fácil y sencilla de navegar | F34: 13 | I34: Servicios | J34: Tiene los mejores tiempos de entrega
A35: Tracking | B35: Digital | C35: Kantar Green | D35: =_xlfn.IFNA(VLOOKUP(C35,Table1[],2,FALSE),"") -> #00B600 | E35: Su sitio online tiene las mejores descripciones de productos | F35: 14 | I35: Servicios | J35: Acepta devoluciones fácilmente
A36: Tracking | B36: Emocional | C36: Kantar Teal | D36: =_xlfn.IFNA(VLOOKUP(C36,Table1[],2,FALSE),"") -> #00E5BA | E36: Es una tienda para mí / con la que me identifico | F36: 1 | I36: Servicios | J36: Ofrece las mejores garantías
A37: Tracking | B37: Emocional | C37: Kantar Teal | D37: =_xlfn.IFNA(VLOOKUP(C37,Table1[],2,FALSE),"") -> #00E5BA | E37: Me ha acompañado a lo largo de mi vida | F37: 2 | I37: Servicios | J37: Es un lugar donde le atienden rápido
A38: Tracking | B38: Emocional | C38: Kantar Teal | D38: =_xlfn.IFNA(VLOOKUP(C38,Table1[],2,FALSE),"") -> #00E5BA | E38: Hace posible que viva mejor cada día | F38: 3 | I38: Servicios | J38: Tiene las opciones de pago adecuadas (crédito, efectivo, pagos digitales)
A39: Tracking | B39: Emocional | C39: Kantar Teal | D39: =_xlfn.IFNA(VLOOKUP(C39,Table1[],2,FALSE),"") -> #00E5BA | E39: Es una marca que me transmite confianza tanto en tienda como en línea | F39: 5 | I39: Servicios | J39: El personal resuelve problemas y dudas
A40: Tracking | B40: Emocional | C40: Kantar Teal | D40: =_xlfn.IFNA(VLOOKUP(C40,Table1[],2,FALSE),"") -> #00E5BA | E40: Me da mayor estatus social | F40: 16 | I40: Servicios | J40: El personal me apoya a comparar en línea si el producto no está disponible en tienda
...

Sheet Empeños
A1: FactorType | B1: FactorName | C1: NodeColor | D1: =VLOOKUP(C1,CATA!A:B,2,FALSE) -> HexColor | E1: Attribute | H1: Path = Right
A2: Path | B2: Confianza y flexibilidad - 20.0% | C2: Kantar Blue | D2: =_xlfn.IFNA(VLOOKUP(C2,Table1[],2,FALSE),"") -> #0060FF | E2: Cuida mejor la prenda/ te la regresan en buen estado | H2: Tracking = Left | K2: Emo-Funcional 34.9%
A3: Tracking | B3: Cuidado al cliente - 22% | C3: Kantar Yellow | D3: =_xlfn.IFNA(VLOOKUP(C3,Table1[],2,FALSE),"") -> #FEDB00 | E3: Cuida mejor la prenda/ te la regresan en buen estado | K3: Emo-Funcional 34.9%
A4: Path | B4: Mejores condiciones y recompensas - 20.0% | C4: Kantar Blue | D4: =_xlfn.IFNA(VLOOKUP(C4,Table1[],2,FALSE),"") -> #0060FF | E4: Después de empeñar, brinda atención para ayudarme a recuperarla | K4: Emo-Funcional 34.9%
A5: Tracking | B5: Cuidado al cliente - 22% | C5: Kantar Yellow | D5: =_xlfn.IFNA(VLOOKUP(C5,Table1[],2,FALSE),"") -> #FEDB00 | E5: Después de empeñar, brinda atención para ayudarme a recuperarla | K5: Emo-Funcional 34.9%
A6: Path | B6: Confianza y flexibilidad - 20.0% | C6: Kantar Blue | D6: =_xlfn.IFNA(VLOOKUP(C6,Table1[],2,FALSE),"") -> #0060FF | E6: Entiende lo que necesito | K6: Emo-Funcional 34.9%
A7: Tracking | B7: Sensación de control - 19% | C7: Kantar Purple | D7: =_xlfn.IFNA(VLOOKUP(C7,Table1[],2,FALSE),"") -> #802AB7 | E7: Entiende lo que necesito | K7: Emo-Funcional 34.9%
A8: Path | B8: Expertos en oro - 4.9% | C8: Kantar Magenta | D8: =_xlfn.IFNA(VLOOKUP(C8,Table1[],2,FALSE),"") -> #C700D3 | E8: Es la marca experta en oro | K8: Experiencia 12%
A9: Tracking | B9: Expertos en oro y planes de pago - 20% | C9: Kantar Orange | D9: =_xlfn.IFNA(VLOOKUP(C9,Table1[],2,FALSE),"") -> #FF5000 | E9: Es la marca experta en oro | K9: Experiencia 12%
A10: Path | B10: Asesoría experta para la toma de decisiones - 41.3% | C10: Kantar Yellow | D10: =_xlfn.IFNA(VLOOKUP(C10,Table1[],2,FALSE),"") -> #FEDB00 | E10: Me brinda la mejor atención | K10: Expertise 21%
A11: Tracking | B11: Cuidado al cliente - 22% | C11: Kantar Yellow | D11: =_xlfn.IFNA(VLOOKUP(C11,Table1[],2,FALSE),"") -> #FEDB00 | E11: Me brinda la mejor atención | K11: Expertise 21%
A12: Path | B12: Cobro - 5.7% | C12: Kantar Green | D12: =_xlfn.IFNA(VLOOKUP(C12,Table1[],2,FALSE),"") -> #00B600 | E12: Me cobra menos al empeñar | K12: Presupuesto 15.7%
A13: Tracking | B13: Pagos y cobro - 11% | C13: Kantar Green | D13: =_xlfn.IFNA(VLOOKUP(C13,Table1[],2,FALSE),"") -> #00B600 | E13: Me cobra menos al empeñar | K13: Tendencia 16.4%
A14: Path | B14: Asesoría experta para la toma de decisiones - 41.3% | C14: Kantar Yellow | D14: =_xlfn.IFNA(VLOOKUP(C14,Table1[],2,FALSE),"") -> #FEDB00 | E14: Me da la mejor asesoría | K14: Tendencia 16.4%
... A16: Path | B16: Confianza y flexibilidad - 20.0% | C16: Kantar Blue | D16: =_xlfn.IFNA(VLOOKUP(C16,Table1[],2,FALSE),"") -> #0060FF | E16: Me genera más confianza | K16: Tendencia 16.4%
A17: Tracking | B17: Sensación de control - 19% | C17: Kantar Purple | D17: =_xlfn.IFNA(VLOOKUP(C17,Table1[],2,FALSE),"") -> #802AB7 | E17: Me genera más confianza
A18: Path | B18: Asesoría experta para la toma de decisiones - 41.3% | C18: Kantar Yellow | D18: =_xlfn.IFNA(VLOOKUP(C18,Table1[],2,FALSE),"") -> #FEDB00 | E18: Tengo el control porque decido cómo armar mi empeño
A19: Path
A20: Path | D20: =_xlfn.IFNA(VLOOKUP(C20,Table1[],2,FALSE),"")
A21: Tracking | B21: Sensación de control - 19% | C21: Kantar Purple | D21: =_xlfn.IFNA(VLOOKUP(C21,Table1[],2,FALSE),"") -> #802AB7 | E21: Tengo el control porque decido cómo armar mi empeño
A22: Path | B22: Mejores condiciones y recompensas - 20.0% | C22: Kantar Blue | D22: =_xlfn.IFNA(VLOOKUP(C22,Table1[],2,FALSE),"") -> #0060FF | E22: Me ofrece más refrendos al empeñar
A23: Tracking | B23: Planes de recompensas y lealtad - 16% | C23: Kantar Blue | D23: =_xlfn.IFNA(VLOOKUP(C23,Table1[],2,FALSE),"") -> #0060FF | E23: Me ofrece más refrendos al empeñar
A24: Path | B24: Comodidad y accesibilidad - 8.0% | C24: Kantar Orange | D24: =_xlfn.IFNA(VLOOKUP(C24,Table1[],2,FALSE),"") -> #FF5000 | E24: Me queda más cerca/ tiene muchas sucursales | K24: Calidad y experiencia en tienda 22.5% (4.9%)
A25: Tracking | B25: Conveniencia y Asesoría - 11% | C25: Kantar Magenta | D25: =_xlfn.IFNA(VLOOKUP(C25,Table1[],2,FALSE),"") -> #C700D3 | E25: Me queda más cerca/ tiene muchas sucursales | K25: Calidad y experiencia en tienda 22.5% (4.9%)
A26: Path | B26: Mejores condiciones y recompensas - 20.0% | C26: Kantar Blue | D26: =_xlfn.IFNA(VLOOKUP(C26,Table1[],2,FALSE),"") -> #0060FF | E26: Ofrece los mejores planes de lealtad | K26: Calidad y experiencia en tienda 22.5% (4.9%)
A27: Tracking | B27: Planes de recompensas y lealtad - 16% | C27: Kantar Blue | D27: =_xlfn.IFNA(VLOOKUP(C27,Table1[],2,FALSE),"") -> #0060FF | E27: Ofrece los mejores planes de lealtad | K27: Variedad y tendencia que encuentro en línea 23% (5%)
A28: Path | B28: Mejores condiciones y recompensas - 20.0% | C28: Kantar Blue | D28: =_xlfn.IFNA(VLOOKUP(C28,Table1[],2,FALSE),"") -> #0060FF | E28: Ofrece los mejores plazos para liquidar | K28: Variedad y tendencia que encuentro en línea 23% (5%)
A29: Tracking | B29: Cuidado al cliente - 22% | C29: Kantar Yellow | D29: =_xlfn.IFNA(VLOOKUP(C29,Table1[],2,FALSE),"") -> #FEDB00 | E29: Ofrece los mejores plazos para liquidar | K29: Variedad y tendencia que encuentro en línea 23% (5%)
A30: Path | B30: Asesoría experta para la toma de decisiones - 41.3% | C30: Kantar Yellow | D30: =_xlfn.IFNA(VLOOKUP(C30,Table1[],2,FALSE),"") -> #FEDB00 | E30: Ofrece más dinero por mi prenda | K30: Variedad y tendencia que encuentro en línea 23% (5%)
A31: Tracking | B31: Pagos y cobro - 11% | C31: Kantar Green | D31: =_xlfn.IFNA(VLOOKUP(C31,Table1[],2,FALSE),"") -> #00B600 | E31: Ofrece más dinero por mi prenda | K31: Para mi estilo y presupuesto 20.3% (4.4%)
A32: Path | B32: Confianza y flexibilidad - 20.0% | C32: Kantar Blue | D32: =_xlfn.IFNA(VLOOKUP(C32,Table1[],2,FALSE),"") -> #0060FF | E32: Ofrece una gran variedad de planes de pago | K32: Para mi estilo y presupuesto 20.3% (4.4%)
A33: Tracking | B33: Expertos en oro y planes de pago - 20% | C33: Kantar Orange | D33: =_xlfn.IFNA(VLOOKUP(C33,Table1[],2,FALSE),"") -> #FF5000 | E33: Ofrece una gran variedad de planes de pago | K33: Para mi estilo y presupuesto 20.3% (4.4%)
A34: Path | B34: Comodidad y accesibilidad - 8.0% | C34: Kantar Orange | D34: =_xlfn.IFNA(VLOOKUP(C34,Table1[],2,FALSE),"") -> #FF5000 | E34: Tiene requisitos fáciles de cumplir | K34: Productos innovadores y exclusivos 15.8% (3.4%)
A35: Tracking | B35: Conveniencia y Asesoría - 11% | C35: Kantar Magenta | D35: =_xlfn.IFNA(VLOOKUP(C35,Table1[],2,FALSE),"") -> #C700D3 | E35: Tiene requisitos fáciles de cumplir | K35: Productos innovadores y exclusivos 15.8% (3.4%)
... A37: Tracking | B37: Cuidado al cliente - 22% | C37: Kantar Yellow | D37: =_xlfn.IFNA(VLOOKUP(C37,Table1[],2,FALSE),"") -> #FEDB00 | E37: Tiene un amplio horario de servicio | K37: Expertise 3.8% (0.8%)
A38: Tracking | K38: Diseño original 14.6% (3.2%)
A39: Tracking | D39: =_xlfn.IFNA(VLOOKUP(C39,Table1[],2,FALSE),"")
A40: Tracking | D40: =_xlfn.IFNA(VLOOKUP(C40,Table1[],2,FALSE),"")
A41: Tracking | D41: =_xlfn.IFNA(VLOOKUP(C41,Table1[],2,FALSE),"")
A42: Tracking | D42: =_xlfn.IFNA(VLOOKUP(C42,Table1[],2,FALSE),"")

Sheet CATA
A1: NodeColor | B1: HexColor
A2: Kantar Purple | B2: #802AB7
A3: Kantar Blue | B3: #0060FF
A4: Kantar Sand | B4: #AEAE9F
A5: Kantar Teal | B5: #00E5BA
A6: Kantar Green | B6: #00B600
A7: Kantar Yellow | B7: #FEDB00
A8: Kantar Orange | B8: #FF5000
A9: Kantar Red | B9: #FA0028
A10: Kantar Magenta | B10: #C700D3
A11: Kantar Light Grey | B11: #D9D9D9

Sheet Template
A1: FactorType | B1: FactorName | C1: NodeColor | D1: =VLOOKUP(C1,CATA!A:B,2,FALSE) -> HexColor | E1: Attribute | H1: Path = Right
A2: Tracking | B2: Emo-Funcional 34.9% | C2: Kantar Green | D2: =_xlfn.IFNA(VLOOKUP(C2,Table1[],2,FALSE),"") -> #00B600 | E2: Buena atención a cliente en tienda física | H2: Tracking = Left | K2: Emo-Funcional 34.9%
A3: Tracking | B3: Emo-Funcional 34.9% | C3: Kantar Green | D3: =_xlfn.IFNA(VLOOKUP(C3,Table1[],2,FALSE),"") -> #00B600 | E3: Buena experiencia en tienda física | K3: Emo-Funcional 34.9%
A4: Tracking | B4: Emo-Funcional 34.9% | C4: Kantar Green | D4: =_xlfn.IFNA(VLOOKUP(C4,Table1[],2,FALSE),"") -> #00B600 | E4: Ofrece productos de buena calidad | K4: Emo-Funcional 34.9%
A5: Tracking | B5: Emo-Funcional 34.9% | C5: Kantar Green | D5: =_xlfn.IFNA(VLOOKUP(C5,Table1[],2,FALSE),"") -> #00B600 | E5: Es una marca con la que me identifico | K5: Emo-Funcional 34.9%
A6: Tracking | B6: Emo-Funcional 34.9% | C6: Kantar Green | D6: =_xlfn.IFNA(VLOOKUP(C6,Table1[],2,FALSE),"") -> #00B600 | E6: Me acompaña en el proceso de compra hasta la entrega | K6: Emo-Funcional 34.9%
A7: Tracking | B7: Emo-Funcional 34.9% | C7: Kantar Green | D7: =_xlfn.IFNA(VLOOKUP(C7,Table1[],2,FALSE),"") -> #00B600 | E7: Es una marca que se adecua a mi estilo | K7: Emo-Funcional 34.9%
A8: Tracking | B8: Experiencia 12% | C8: Kantar Blue | D8: =_xlfn.IFNA(VLOOKUP(C8,Table1[],2,FALSE),"") -> #0060FF | E8: Variedad de productos para decorar mi hogar | K8: Experiencia 12%
A9: Tracking | B9: Experiencia 12% | C9: Kantar Blue | D9: =_xlfn.IFNA(VLOOKUP(C9,Table1[],2,FALSE),"") -> #0060FF | E9: Buena experiencia en tienda en línea | K9: Experiencia 12%
A10: Tracking | B10: Expertise 21% | C10: Kantar Yellow | D10: =_xlfn.IFNA(VLOOKUP(C10,Table1[],2,FALSE),"") -> #FEDB00 | E10: Me inspira a decorar mi hogar | K10: Expertise 21%
A11: Tracking | B11: Expertise 21% | C11: Kantar Yellow | D11: =_xlfn.IFNA(VLOOKUP(C11,Table1[],2,FALSE),"") -> #FEDB00 | E11: Experta en decoración | K11: Expertise 21%
A12: Tracking | B12: Presupuesto 15.7% | C12: Kantar Teal | D12: =_xlfn.IFNA(VLOOKUP(C12,Table1[],2,FALSE),"") -> #00E5BA | E12: Opciones para todos los presupuestos | K12: Presupuesto 15.7%
A13: Tracking | B13: Tendencia 16.4% | C13: Kantar Magenta | D13: =_xlfn.IFNA(VLOOKUP(C13,Table1[],2,FALSE),"") -> #C700D3 | E13: Tiene artículos de moda | K13: Tendencia 16.4%
A14: Tracking | B14: Tendencia 16.4% | C14: Kantar Magenta | D14: =_xlfn.IFNA(VLOOKUP(C14,Table1[],2,FALSE),"") -> #C700D3 | E14: Esta innovando constantemente | K14: Tendencia 16.4%
... A16: Tracking | B16: Tendencia 16.4% | C16: Kantar Magenta | D16: =_xlfn.IFNA(VLOOKUP(C16,Table1[],2,FALSE),"") -> #C700D3 | E16: Vende artículos con diseño original | K16: Tendencia 16.4%
A17: Tracking | D17: =_xlfn.IFNA(VLOOKUP(C17,Table1[],2,FALSE),"")
A18: Tracking | D18: =_xlfn.IFNA(VLOOKUP(C18,Table1[],2,FALSE),"")
A19: Tracking | D19: =_xlfn.IFNA(VLOOKUP(C19,Table1[],2,FALSE),"")
A20: Tracking | D20: =_xlfn.IFNA(VLOOKUP(C20,Table1[],2,FALSE),"")
A21: Tracking | D21: =_xlfn.IFNA(VLOOKUP(C21,Table1[],2,FALSE),"")
A22: Tracking | D22: =_xlfn.IFNA(VLOOKUP(C22,Table1[],2,FALSE),"")
A23: Tracking | D23: =_xlfn.IFNA(VLOOKUP(C23,Table1[],2,FALSE),"")
A24: Path | B24: Calidad y experiencia en tienda 22.5% (4.9%) | C24: Kantar Green | D24: =_xlfn.IFNA(VLOOKUP(C24,Table1[],2,FALSE),"") -> #00B600 | E24: Buena experiencia en tienda física | K24: Calidad y experiencia en tienda 22.5% (4.9%)
A25: Path | B25: Calidad y experiencia en tienda 22.5% (4.9%) | C25: Kantar Green | D25: =_xlfn.IFNA(VLOOKUP(C25,Table1[],2,FALSE),"") -> #00B600 | E25: Buena atención a cliente en tienda física | K25: Calidad y experiencia en tienda 22.5% (4.9%)
A26: Path | B26: Calidad y experiencia en tienda 22.5% (4.9%) | C26: Kantar Green | D26: =_xlfn.IFNA(VLOOKUP(C26,Table1[],2,FALSE),"") -> #00B600 | E26: Ofrece productos de buena calidad | K26: Calidad y experiencia en tienda 22.5% (4.9%)
A27: Path | B27: Variedad y tendencia que encuentro en línea 23% (5%) | C27: Kantar Magenta | D27: =_xlfn.IFNA(VLOOKUP(C27,Table1[],2,FALSE),"") -> #C700D3 | E27: Variedad de productos para decorar mi hogar | K27: Variedad y tendencia que encuentro en línea 23% (5%)
A28: Path | B28: Variedad y tendencia que encuentro en línea 23% (5%) | C28: Kantar Magenta | D28: =_xlfn.IFNA(VLOOKUP(C28,Table1[],2,FALSE),"") -> #C700D3 | E28: Buena experiencia en tienda en línea | K28: Variedad y tendencia que encuentro en línea 23% (5%)
A29: Path | B29: Variedad y tendencia que encuentro en línea 23% (5%) | C29: Kantar Magenta | D29: =_xlfn.IFNA(VLOOKUP(C29,Table1[],2,FALSE),"") -> #C700D3 | E29: Me acompaña en el proceso de compra hasta la entrega | K29: Variedad y tendencia que encuentro en línea 23% (5%)
A30: Path | B30: Variedad y tendencia que encuentro en línea 23% (5%) | C30: Kantar Magenta | D30: =_xlfn.IFNA(VLOOKUP(C30,Table1[],2,FALSE),"") -> #C700D3 | E30: Tiene artículos de moda | K30: Variedad y tendencia que encuentro en línea 23% (5%)
A31: Path | B31: Para mi estilo y presupuesto 20.3% (4.4%) | C31: Kantar Red | D31: =_xlfn.IFNA(VLOOKUP(C31,Table1[],2,FALSE),"") -> #FA0028 | E31: Opciones para todos los presupuestos | K31: Para mi estilo y presupuesto 20.3% (4.4%)
A32: Path | B32: Para mi estilo y presupuesto 20.3% (4.4%) | C32: Kantar Red | D32: =_xlfn.IFNA(VLOOKUP(C32,Table1[],2,FALSE),"") -> #FA0028 | E32: Es una marca que se adecua a mi estilo | K32: Para mi estilo y presupuesto 20.3% (4.4%)
A33: Path | B33: Para mi estilo y presupuesto 20.3% (4.4%) | C33: Kantar Red | D33: =_xlfn.IFNA(VLOOKUP(C33,Table1[],2,FALSE),"") -> #FA0028 | E33: Es una marca con la que me identifico | K33: Para mi estilo y presupuesto 20.3% (4.4%)
A34: Path | B34: Productos innovadores y exclusivos 15.8% (3.4%) | C34: Kantar Blue | D34: =_xlfn.IFNA(VLOOKUP(C34,Table1[],2,FALSE),"") -> #0060FF | E34: Vende productos exclusivos | K34: Productos innovadores y exclusivos 15.8% (3.4%)
A35: Path | B35: Productos innovadores y exclusivos 15.8% (3.4%) | C35: Kantar Blue | D35: =_xlfn.IFNA(VLOOKUP(C35,Table1[],2,FALSE),"") -> #0060FF | E35: Esta innovando constantemente | K35: Productos innovadores y exclusivos 15.8% (3.4%)
... A38: Path | B38: Diseño original 14.6% (3.2%) | C38: Kantar Orange | D38: =_xlfn.IFNA(VLOOKUP(C38,Table1[],2,FALSE),"") -> #FF5000 | E38: Vende artículos con diseño original | K38: Diseño original 14.6% (3.2%)
A39: Path | D39: =_xlfn.IFNA(VLOOKUP(C39,Table1[],2,FALSE),"")
A40: Path | D40: =_xlfn.IFNA(VLOOKUP(C40,Table1[],2,FALSE),"")
A41: Path | D41: =_xlfn.IFNA(VLOOKUP(C41,Table1[],2,FALSE),"")
A42: Path | D42: =_xlfn.IFNA(VLOOKUP(C42,Table1[],2,FALSE),"")

Sheet BSA Protex IMG w Imp
A1: FactorType | B1: FactorName | C1: NodeColor | D1: =VLOOKUP(C1,CATA!A:B,2,FALSE) -> HexColor | E1: Attribute | H1: Path = Right
A2: Path | B2: Antibacterial - 7.5 | C2: Kantar Blue | D2: =_xlfn.IFNA(VLOOKUP(C2,Table1[],2,FALSE),"") -> #0060FF | E2: Provides long lasting antibacterial protection | H2: Tracking = Left
A3: Path | B3: Antibacterial - 7.5 | C3: Kantar Blue | D3: =_xlfn.IFNA(VLOOKUP(C3,Table1[],2,FALSE),"") -> #0060FF | E3: Kills germs provides antibacterial protection
A4: Path | B4: Attractive package that show the fragrance - 11.6 | C4: Kantar Magenta | D4: =_xlfn.IFNA(VLOOKUP(C4,Table1[],2,FALSE),"") -> #C700D3 | E4: Has a packaging that conveys an attractive fragrance
A5: Path | B5: Attractive package that show the fragrance - 11.6 | C5: Kantar Magenta | D5: =_xlfn.IFNA(VLOOKUP(C5,Table1[],2,FALSE),"") -> #C700D3 | E5: Has attractive packaging
A6: Path | B6: Expert in skin health - 1.8 | C6: Kantar Teal | D6: =_xlfn.IFNA(VLOOKUP(C6,Table1[],2,FALSE),"") -> #00E5BA | E6: Is expert in skin health
A7: Path | B7: Experts recommendation I follow - 19.7 | C7: Kantar Blue | D7: =_xlfn.IFNA(VLOOKUP(C7,Table1[],2,FALSE),"") -> #0060FF | E7: Is recommended by dermatologists
A8: Path | B8: Experts recommendation I follow - 19.7 | C8: Kantar Blue | D8: =_xlfn.IFNA(VLOOKUP(C8,Table1[],2,FALSE),"") -> #0060FF | E8: Makes me feel like an expert in skin care
A9: Path | B9: For my dry skin - 8.3 | C9: Kantar Orange | D9: =_xlfn.IFNA(VLOOKUP(C9,Table1[],2,FALSE),"") -> #FF5000 | E9: Does not dry out nor irritate the skin
A10: Path | B10: For my dry skin - 8.3 | C10: Kantar Orange | D10: =_xlfn.IFNA(VLOOKUP(C10,Table1[],2,FALSE),"") -> #FF5000 | E10: Provides the care my skin needs
A11: Path | B11: Fragrances for starting the day - 9.9 | C11: Kantar Yellow | D11: =_xlfn.IFNA(VLOOKUP(C11,Table1[],2,FALSE),"") -> #FEDB00 | E11: Has the scents that I like the most
A12: Path | B12: Fragrances for starting the day - 9.9 | C12: Kantar Yellow | D12: =_xlfn.IFNA(VLOOKUP(C12,Table1[],2,FALSE),"") -> #FEDB00 | E12: Fragrance that helps me start the day with energy
A13: Path | B13: Fragrances for starting the day - 9.9 | C13: Kantar Yellow | D13: =_xlfn.IFNA(VLOOKUP(C13,Table1[],2,FALSE),"") -> #FEDB00 | E13: Helps me feel more attractive
A14: Path | B14: Fragrances for starting the day - 9.9 | C14: Kantar Yellow | D14: =_xlfn.IFNA(VLOOKUP(C14,Table1[],2,FALSE),"") -> #FEDB00 | E14: Has aromas that improve my mood
... A65: Tracking | B65: Technology and recommendation - 11.5 | C65: Kantar Yellow | D65: =_xlfn.IFNA(VLOOKUP(C65,Table1[],2,FALSE),"") -> #FEDB00 | E65: Is recommended by dermatologists

Sheet BSA Protex IMG
A1: FactorType | B1: FactorName | C1: NodeColor | D1: =VLOOKUP(C1,CATA!A:B,2,FALSE) -> HexColor | E1: Attribute | H1: Path = Right
A2: Tracking | B2: Advanced skin defense | C2: Kantar Blue | D2: =_xlfn.IFNA(VLOOKUP(C2,Table1[],2,FALSE),"") -> #0060FF | E2: Helps me eliminate skin impurities | H2: Tracking = Left
A3: Tracking | B3: Advanced skin defense | C3: Kantar Blue | D3: =_xlfn.IFNA(VLOOKUP(C3,Table1[],2,FALSE),"") -> #0060FF | E3: Provides long lasting antibacterial protection
A4: Tracking | B4: Advanced skin defense | C4: Kantar Blue | D4: =_xlfn.IFNA(VLOOKUP(C4,Table1[],2,FALSE),"") -> #0060FF | E4: Kills germs provides antibacterial protection
A5: Tracking | B5: Advanced skin defense | C5: Kantar Blue | D5: =_xlfn.IFNA(VLOOKUP(C5,Table1[],2,FALSE),"") -> #0060FF | E5: Helps prevent skin problems
A6: Path | B6: Antibacterial | C6: Kantar Blue | D6: =_xlfn.IFNA(VLOOKUP(C6,Table1[],2,FALSE),"") -> #0060FF | E6: Provides long lasting antibacterial protection
A7: Path | B7: Antibacterial | C7: Kantar Blue | D7: =_xlfn.IFNA(VLOOKUP(C7,Table1[],2,FALSE),"") -> #0060FF | E7: Kills germs provides antibacterial protection
A8: Path | B8: Attractive package that show the fragrance | C8: Kantar Magenta | D8: =_xlfn.IFNA(VLOOKUP(C8,Table1[],2,FALSE),"") -> #C700D3 | E8: Has a packaging that conveys an attractive fragrance
A9: Path | B9: Attractive package that show the fragrance | C9: Kantar Magenta | D9: =_xlfn.IFNA(VLOOKUP(C9,Table1[],2,FALSE),"") -> #C700D3 | E9: Has attractive packaging
A10: Tracking | B10: Benefits and identification | C10: Kantar Purple | D10: =_xlfn.IFNA(VLOOKUP(C10,Table1[],2,FALSE),"") -> #802AB7 | E10: Is worth paying more for
A11: Tracking | B11: Benefits and identification | C11: Kantar Purple | D11: =_xlfn.IFNA(VLOOKUP(C11,Table1[],2,FALSE),"") -> #802AB7 | E11: Nourishes my skin
A12: Tracking | B12: Benefits and identification | C12: Kantar Purple | D12: =_xlfn.IFNA(VLOOKUP(C12,Table1[],2,FALSE),"") -> #802AB7 | E12: Moisturizes my skin
A13: Tracking | B13: Benefits and identification | C13: Kantar Purple | D13: =_xlfn.IFNA(VLOOKUP(C13,Table1[],2,FALSE),"") -> #802AB7 | E13: Does not dry out nor irritate the skin
A14: Tracking | B14: Benefits and identification | C14: Kantar Purple | D14: =_xlfn.IFNA(VLOOKUP(C14,Table1[],2,FALSE),"") -> #802AB7 | E14: Provides the care my skin needs
... A65: Path | B65: Trusted family care | C65: Kantar Purple | D65: =_xlfn.IFNA(VLOOKUP(C65,Table1[],2,FALSE),"") -> #802AB7 | E65: Makes me feel clean throughout the day

Sheet ACT Placer Ciudad Posadas
A1: FactorType | B1: FactorName | C1: NodeColor | D1: =VLOOKUP(C1,CATA!A:B,2,FALSE) -> HexColor | E1: Attribute | H1: Path = Right
A2: Path | B2: Availability (16.2%) | C2: Kantar Green | D2: =_xlfn.IFNA(VLOOKUP(C2,Table1[],2,FALSE),"") -> #00B600 | E2: Had availability for my travel dates | H2: Tracking = Left
A3: Path | B3: Experience and location I wanted (31.7%) | C3: Kantar Orange | D3: =_xlfn.IFNA(VLOOKUP(C3,Table1[],2,FALSE),"") -> #FF5000 | E3: It was on the location I was looking for
A4: Path | B4: Experience and location I wanted (31.7%) | C4: Kantar Orange | D4: =_xlfn.IFNA(VLOOKUP(C4,Table1[],2,FALSE),"") -> #FF5000 | E4: Offered the experience I was looking for
A5: Path | B5: Informative websites and reviews (14.8%) | C5: Kantar Blue | D5: =_xlfn.IFNA(VLOOKUP(C5,Table1[],2,FALSE),"") -> #0060FF | E5: It has good reviews from customers
A6: Path | B6: Informative websites and reviews (14.8%) | C6: Kantar Blue | D6: =_xlfn.IFNA(VLOOKUP(C6,Table1[],2,FALSE),"") -> #0060FF | E6: It has good reviews specifically on Tripadvisor
A7: Path | B7: Informative websites and reviews (14.8%) | C7: Kantar Blue | D7: =_xlfn.IFNA(VLOOKUP(C7,Table1[],2,FALSE),"") -> #0060FF | E7: The hotel website was informative and easy to use
A8: Path | B8: On promotion (7.9%) | C8: Kantar Yellow | D8: =_xlfn.IFNA(VLOOKUP(C8,Table1[],2,FALSE),"") -> #FEDB00 | E8: It was on promotion
A9: Path | B9: Tempting promotional package (29.4%) | C9: Kantar Purple | D9: =_xlfn.IFNA(VLOOKUP(C9,Table1[],2,FALSE),"") -> #802AB7 | E9: It had a good flight plus hotel offer
A10: Path | B10: Tempting promotional package (29.4%) | C10: Kantar Purple | D10: =_xlfn.IFNA(VLOOKUP(C10,Table1[],2,FALSE),"") -> #802AB7 | E10: It was within the price range I was looking for
A11: Path | B11: Tempting promotional package (29.4%) | C11: Kantar Purple | D11: =_xlfn.IFNA(VLOOKUP(C11,Table1[],2,FALSE),"") -> #802AB7 | E11: The photos looked tempting
A12: Path | D12: =_xlfn.IFNA(VLOOKUP(C12,Table1[],2,FALSE),"")
A13: Path | D13: =_xlfn.IFNA(VLOOKUP(C13,Table1[],2,FALSE),"")
A14: Path | D14: =_xlfn.IFNA(VLOOKUP(C14,Table1[],2,FALSE),"")
A15: Path | D15: =_xlfn.IFNA(VLOOKUP(C15,Table1[],2,FALSE),"")
A16: Path | D16: =_xlfn.IFNA(VLOOKUP(C16,Table1[],2,FALSE),"")
A17: Path | D17: =_xlfn.IFNA(VLOOKUP(C17,Table1[],2,FALSE),"")
A18: Path | D18: =_xlfn.IFNA(VLOOKUP(C18,Table1[],2,FALSE),"")
A19: Path | D19: =_xlfn.IFNA(VLOOKUP(C19,Table1[],2,FALSE),"")
A20: Path | D20: =_xlfn.IFNA(VLOOKUP(C20,Table1[],2,FALSE),"")
A21: Tracking | B21: Experience preview (23.0%) | C21: Kantar Red | D21: =_xlfn.IFNA(VLOOKUP(C21,Table1[],2,FALSE),"") -> #FA0028 | E21: Offered the experience I was looking for
A22: Tracking | B22: Experience preview (23.0%) | C22: Kantar Red | D22: =_xlfn.IFNA(VLOOKUP(C22,Table1[],2,FALSE),"") -> #FA0028 | E22: The hotel website was informative and easy to use
A23: Tracking | B23: Presence and accesibility (25.3%) | C23: Kantar Teal | D23: =_xlfn.IFNA(VLOOKUP(C23,Table1[],2,FALSE),"") -> #00E5BA | E23: Had availability for my travel dates
A24: Tracking | B24: Presence and accesibility (25.3%) | C24: Kantar Teal | D24: =_xlfn.IFNA(VLOOKUP(C24,Table1[],2,FALSE),"") -> #00E5BA | E24: It was on the location I was looking for
A25: Tracking | B25: Presence and accesibility (25.3%) | C25: Kantar Teal | D25: =_xlfn.IFNA(VLOOKUP(C25,Table1[],2,FALSE),"") -> #00E5BA | E25: It was within the price range I was looking for
A26: Tracking | B26: On promotion (5.5%) | C26: Kantar Yellow | D26: =_xlfn.IFNA(VLOOKUP(C26,Table1[],2,FALSE),"") -> #FEDB00 | E26: It was on promotion
A27: Tracking | B27: Options and visual stimulation (23.0%) | C27: Kantar Sand | D27: =_xlfn.IFNA(VLOOKUP(C27,Table1[],2,FALSE),"") -> #AEAE9F | E27: It has good reviews from customers
A28: Tracking | B28: Options and visual stimulation (23.0%) | C28: Kantar Sand | D28: =_xlfn.IFNA(VLOOKUP(C28,Table1[],2,FALSE),"") -> #AEAE9F | E28: The photos looked tempting
A29: Tracking | B29: Promotion and reliability (23.3%) | C29: Kantar Magenta | D29: =_xlfn.IFNA(VLOOKUP(C29,Table1[],2,FALSE),"") -> #C700D3 | E29: It had a good flight plus hotel offer
A30: Tracking | B30: Promotion and reliability (23.3%) | C30: Kantar Magenta | D30: =_xlfn.IFNA(VLOOKUP(C30,Table1[],2,FALSE),"") -> #C700D3 | E30: It has good reviews specifically on Tripadvisor
A31: Tracking | D31: =_xlfn.IFNA(VLOOKUP(C31,Table1[],2,FALSE),"")
A32: Tracking | D32: =_xlfn.IFNA(VLOOKUP(C32,Table1[],2,FALSE),"")
A33: Tracking | D33: =_xlfn.IFNA(VLOOKUP(C33,Table1[],2,FALSE),"")
A34: Tracking | D34: =_xlfn.IFNA(VLOOKUP(C34,Table1[],2,FALSE),"")
A35: Tracking | D35: =_xlfn.IFNA(VLOOKUP(C35,Table1[],2,FALSE),"")
A36: Tracking | D36: =_xlfn.IFNA(VLOOKUP(C36,Table1[],2,FALSE),"")
A37: Tracking | D37: =_xlfn.IFNA(VLOOKUP(C37,Table1[],2,FALSE),"")
A38: Tracking | D38: =_xlfn.IFNA(VLOOKUP(C38,Table1[],2,FALSE),"")
A39: Tracking | D39: =_xlfn.IFNA(VLOOKUP(C39,Table1[],2,FALSE),"")
A40: Tracking | D40: =_xlfn.IFNA(VLOOKUP(C40,Table1[],2,FALSE),"")
...

Sheet Placer Ciudad Posadas
A1: FactorType | B1: FactorName | C1: NodeColor | D1: =VLOOKUP(C1,CATA!A:B,2,FALSE) -> HexColor | E1: Attribute | F1: Comparación | H1: Path = Right
A2: Path | B2: Cares about me and the environment (22.8%) | C2: Kantar Green | D2: =_xlfn.IFNA(VLOOKUP(C2,Table1[],2,FALSE),"") -> #00B600 | E2: Provides experiences for my physical and mental wellbeing | F2: TOTAL | H2: Tracking = Left
A3: Path | B3: Cares about me and the environment (22.8%) | C3: Kantar Green | D3: =_xlfn.IFNA(VLOOKUP(C3,Table1[],2,FALSE),"") -> #00B600 | E3: Cares about the environment and takes action to protect it | F3: TOTAL
A4: Path | B4: Family escape from routine (7.3%) | C4: Kantar Purple | D4: =_xlfn.IFNA(VLOOKUP(C4,Table1[],2,FALSE),"") -> #802AB7 | E4: Allows you to disconnect from the routine | F4: TOTAL
A5: Path | B5: Family escape from routine (7.3%) | C5: Kantar Purple | D5: =_xlfn.IFNA(VLOOKUP(C5,Table1[],2,FALSE),"") -> #802AB7 | E5: Its hotels are ideal for the whole family | F5: TOTAL
A6: Path | B6: Infrastructure that suits my needs (17.8%) | C6: Kantar Blue | D6: =_xlfn.IFNA(VLOOKUP(C6,Table1[],2,FALSE),"") -> #0060FF | E6: Provides facilities to spend quality time with my companions | F6: TOTAL
A7: Path | B7: Infrastructure that suits my needs (17.8%) | C7: Kantar Blue | D7: =_xlfn.IFNA(VLOOKUP(C7,Table1[],2,FALSE),"") -> #0060FF | E7: Adapts to my lifestyle and needs | F7: TOTAL
A8: Path | B8: Infrastructure that suits my needs (17.8%) | C8: Kantar Blue | D8: =_xlfn.IFNA(VLOOKUP(C8,Table1[],2,FALSE),"") -> #0060FF | E8: Equipped with appropriate technology for my trip | F8: TOTAL
A9: Path | B9: Loyalty program (13.7%) | C9: Kantar Teal | D9: =_xlfn.IFNA(VLOOKUP(C9,Table1[],2,FALSE),"") -> #00E5BA | E9: Has the best loyalty frequent guest program | F9: TOTAL
A10: Path | B10: Memorable legacy and prestige (20.0%) | C10: Kantar Yellow | D10: =_xlfn.IFNA(VLOOKUP(C10,Table1[],2,FALSE),"") -> #FEDB00 | E10: It is a prestigious hotel chain | F10: TOTAL
A11: Path | B11: Memorable legacy and prestige (20.0%) | C11: Kantar Yellow | D11: =_xlfn.IFNA(VLOOKUP(C11,Table1[],2,FALSE),"") -> #FEDB00 | E11: Helps create experiences to always remember | F11: TOTAL
A12: Path | B12: Memorable legacy and prestige (20.0%) | C12: Kantar Yellow | D12: =_xlfn.IFNA(VLOOKUP(C12,Table1[],2,FALSE),"") -> #FEDB00 | E12: It is a brand with tradition | F12: TOTAL
A13: Path | B13: Hospitality and culinary experience (18.4%) | C13: Kantar Orange | D13: =_xlfn.IFNA(VLOOKUP(C13,Table1[],2,FALSE),"") -> #FF5000 | E13: Its hotels offer an adequate selection of food and beverages | F13: TOTAL
A14: Path | B14: Hospitality and culinary experience (18.4%) | C14: Kantar Orange | D14: =_xlfn.IFNA(VLOOKUP(C14,Table1[],2,FALSE),"") -> #FF5000 | E14: Its hotels have a pleasant atmosphere | F14: TOTAL
... A16: Path | B16: NA | C16: Kantar Light Grey | D16: =_xlfn.IFNA(VLOOKUP(C16,Table1[],2,FALSE),"") -> #D9D9D9 | E16: Offers good entertainment options | F16: PLAYA
A17: Path | D17: =_xlfn.IFNA(VLOOKUP(C17,Table1[],2,FALSE),"")
A18: Path | D18: =_xlfn.IFNA(VLOOKUP(C18,Table1[],2,FALSE),"")
A19: Path | D19: =_xlfn.IFNA(VLOOKUP(C19,Table1[],2,FALSE),"")
A20: Path | D20: =_xlfn.IFNA(VLOOKUP(C20,Table1[],2,FALSE),"")
A21: Tracking | B21: Environmental Care | C21: Kantar Green | D21: =_xlfn.IFNA(VLOOKUP(C21,Table1[],2,FALSE),"") -> #00B600 | E21: Cares about the environment and takes action to protect it | F21: CATEGORIA
A22: Tracking | B22: Holistic Stay Experience | C22: Kantar Red | D22: =_xlfn.IFNA(VLOOKUP(C22,Table1[],2,FALSE),"") -> #FA0028 | E22: Provides experiences for my physical and mental wellbeing | F22: CATEGORIA
A23: Tracking | B23: Holistic Stay Experience | C23: Kantar Red | D23: =_xlfn.IFNA(VLOOKUP(C23,Table1[],2,FALSE),"") -> #FA0028 | E23: Equipped with appropriate technology for my trip | F23: CATEGORIA
A24: Tracking | B24: Holistic Stay Experience | C24: Kantar Red | D24: =_xlfn.IFNA(VLOOKUP(C24,Table1[],2,FALSE),"") -> #FA0028 | E24: The hotel staff is friendly and attentive | F24: CATEGORIA
A25: Tracking | B25: Lifestyle Alignment | C25: Kantar Magenta | D25: =_xlfn.IFNA(VLOOKUP(C25,Table1[],2,FALSE),"") -> #C700D3 | E25: Its hotels are ideal for the whole family | F25: CATEGORIA
A26: Tracking | B26: Lifestyle Alignment | C26: Kantar Magenta | D26: =_xlfn.IFNA(VLOOKUP(C26,Table1[],2,FALSE),"") -> #C700D3 | E26: Adapts to my lifestyle and needs | F26: CATEGORIA
A27: Tracking | B27: Lifestyle Alignment | C27: Kantar Magenta | D27: =_xlfn.IFNA(VLOOKUP(C27,Table1[],2,FALSE),"") -> #C700D3 | E27: Its hotels have a pleasant atmosphere | F27: CATEGORIA
A28: Tracking | B28: Lifestyle Alignment | C28: Kantar Magenta | D28: =_xlfn.IFNA(VLOOKUP(C28,Table1[],2,FALSE),"") -> #C700D3 | E28: Helps create experiences to always remember | F28: CATEGORIA
A29: Tracking | B29: Loyalty Program | C29: Kantar Teal | D29: =_xlfn.IFNA(VLOOKUP(C29,Table1[],2,FALSE),"") -> #00E5BA | E29: Has the best loyalty frequent guest program | F29: CATEGORIA
A30: Tracking | B30: Shared Experience & Comfort | C30: Kantar Sand | D30: =_xlfn.IFNA(VLOOKUP(C30,Table1[],2,FALSE),"") -> #AEAE9F | E30: Provides facilities to spend quality time with my companions | F30: CATEGORIA
A31: Tracking | B31: Shared Experience & Comfort | C31: Kantar Sand | D31: =_xlfn.IFNA(VLOOKUP(C31,Table1[],2,FALSE),"") -> #AEAE9F | E31: Allows you to disconnect from the routine | F31: CATEGORIA
A32: Tracking | B32: Shared Experience & Comfort | C32: Kantar Sand | D32: =_xlfn.IFNA(VLOOKUP(C32,Table1[],2,FALSE),"") -> #AEAE9F | E32: It is a prestigious hotel chain | F32: CATEGORIA
... A49: Tracking | B49: All in one entertainment (25.9%) | C49: Kantar Orange | D49: =_xlfn.IFNA(VLOOKUP(C49,Table1[],2,FALSE),"") -> #FF5000 | E49: Its hotels offer an adequate selection of food and beverages | F49: PLAYA
A50: Tracking | D50: =_xlfn.IFNA(VLOOKUP(C50,Table1[],2,FALSE),"")
A51: Tracking | D51: =_xlfn.IFNA(VLOOKUP(C51,Table1[],2,FALSE),"")
A52: Tracking | D52: =_xlfn.IFNA(VLOOKUP(C52,Table1[],2,FALSE),"")
A53: Tracking | D53: =_xlfn.IFNA(VLOOKUP(C53,Table1[],2,FALSE),"")
A54: Tracking | D54: =_xlfn.IFNA(VLOOKUP(C54,Table1[],2,FALSE),"")
A55: Tracking | D55: =_xlfn.IFNA(VLOOKUP(C55,Table1[],2,FALSE),"")
A56: Tracking | D56: =_xlfn.IFNA(VLOOKUP(C56,Table1[],2,FALSE),"")
A57: Tracking | D57: =_xlfn.IFNA(VLOOKUP(C57,Table1[],2,FALSE),"")
...

Sheet Lipton BR vs H2OH BR
A1: FactorType | B1: FactorName | C1: NodeColor | D1: =VLOOKUP(C1,CATA!A:B,2,FALSE) -> HexColor | E1: Attribute | F1: Group | G1: Full ATT Label | H1: Path = Right
A2: Path | B2: Convenient And Attractive Package - 5.4% (60.7%) | C2: Kantar Teal | D2: =_xlfn.IFNA(VLOOKUP(C2,Table1[],2,FALSE),"") -> #00E5BA | E2: Attractive packaging | F2: Activador | H2: Tracking = Left | K2: Factor Label | L2: Factor Label w Imp | M2: Factor Label w Norm Imp
A3: Path | B3: Convenient And Attractive Package - 5.4% (60.7%) | C3: Kantar Teal | D3: =_xlfn.IFNA(VLOOKUP(C3,Table1[],2,FALSE),"") -> #00E5BA | E3: Convenient presentations | F3: Activador | K3: Accessible | L3: Accessible (3.5%) | M3: Accessible - 3.5% (39.3%)
A4: Path | B4: Accessible - 3.5% (39.3%) | C4: Kantar Purple | D4: =_xlfn.IFNA(VLOOKUP(C4,Table1[],2,FALSE),"") -> #802AB7 | E4: Easy to find | F4: Activador | K4: Balanced Recharge | L4: Balanced Recharge (3.3%) | M4: Balanced Recharge - 3.3% (23.5%)
A5: Path | B5: N/A | C5: Kantar Light Grey | D5: =_xlfn.IFNA(VLOOKUP(C5,Table1[],2,FALSE),"") -> #D9D9D9 | E5: Engaging advertising | F5: Activador | K5: Bright Side Of Life | L5: Bright Side Of Life (1.8%) | M5: Bright Side Of Life - 1.8% (13.5%)
A6: Path | B6: Accessible - 3.5% (39.3%) | C6: Kantar Purple | D6: =_xlfn.IFNA(VLOOKUP(C6,Table1[],2,FALSE),"") -> #802AB7 | E6: Fair value | F6: Activador | K6: Convenient And Attractive Package | L6: Convenient And Attractive Package (5.4%) | M6: Convenient And Attractive Package - 5.4% (60.7%)
A7: Path | B7: Flavor And Quality - 2.7% (19.1%) | C7: Kantar Blue | D7: =_xlfn.IFNA(VLOOKUP(C7,Table1[],2,FALSE),"") -> #0060FF | E7: Flavor | F7: Funcionales | K7: Different | L7: Different (13.3%) | M7: Different - 13.3% (27.2%)
A8: Path | B8: Enhancing My Journey - 3.5% (46.7%) | C8: Kantar Teal | D8: =_xlfn.IFNA(VLOOKUP(C8,Table1[],2,FALSE),"") -> #00E5BA | E8: For enjoying when I am alone | F8: Ocasiones | K8: Enhancing My Journey | L8: Enhancing My Journey (3.5%) | M8: Enhancing My Journey - 3.5% (46.7%)
A9: Path | B9: N/A | C9: Kantar Light Grey | D9: =_xlfn.IFNA(VLOOKUP(C9,Table1[],2,FALSE),"") -> #D9D9D9 | E9: For everyday | F9: Ocasiones | K9: Flavor And Quality | L9: Flavor And Quality (2.7%) | M9: Flavor And Quality - 2.7% (19.1%)
A10: Path | B10: For Me To Indulge - 5.1% (39.2%) | C10: Kantar Purple | D10: =_xlfn.IFNA(VLOOKUP(C10,Table1[],2,FALSE),"") -> #802AB7 | E10: For someone like me | F10: Posicionamiento | K10: For Me To Indulge | L10: For Me To Indulge (5.1%) | M10: For Me To Indulge - 5.1% (39.2%)
A11: Path | B11: Great Legacy - 0.8% (11.1%) | C11: Kantar Yellow | D11: =_xlfn.IFNA(VLOOKUP(C11,Table1[],2,FALSE),"") -> #FEDB00 | E11: Great career | F11: Emocional | K11: Good To Be Seen Drinking | L11: Good To Be Seen Drinking (1.8%) | M11: Good To Be Seen Drinking - 1.8% (13.7%)
A12: Path | B12: Distinguished Style - 2.4% (31.6%) | C12: Kantar Green | D12: =_xlfn.IFNA(VLOOKUP(C12,Table1[],2,FALSE),"") -> #00B600 | E12: It is sophisticated | F12: Emocional | K12: Great Career | L12: Great Career (0.8%) | M12: Great Career - 0.8% (11.1%)
A13: Path | B13: Relaxation - 2.3% (16.4%) | C13: Kantar Orange | D13: =_xlfn.IFNA(VLOOKUP(C13,Table1[],2,FALSE),"") -> #FF5000 | E13: Helps you relax your body and mind | F13: Funcionales | K13: Low Sugar Variety | L13: Low Sugar Variety (1.7%) | M13: Low Sugar Variety - 1.7% (12.1%)
A14: Path | B14: Bright Side Of Life - 1.8% (13.5%) | C14: Kantar Orange | D14: =_xlfn.IFNA(VLOOKUP(C14,Table1[],2,FALSE),"") -> #FF5000 | E14: Helps you see the good side of life | F14: Posicionamiento | K14: Meals | L14: Meals (2.2%) | M14: Meals - 2.2% (29.9%)
... A25: Path | B25: Pleasant Sensation - 1.6% (11.3%) | C25: Kantar Yellow | D25: =_xlfn.IFNA(VLOOKUP(C25,Table1[],2,FALSE),"") -> #FEDB00 | E25: Leaves a pleasant sensation | F25: Funcionales | K25: Worth | L25: Worth (14.3%) | M25: Worth - 14.3% (29.2%)
A26: Path | B26: Balanced Recharge - 3.3% (23.5%) | C26: Kantar Magenta | D26: =_xlfn.IFNA(VLOOKUP(C26,Table1[],2,FALSE),"") -> #C700D3 | E26: Light and balanced | F26: Funcionales
A27: Path | B27: N/A | C27: Kantar Light Grey | D27: =_xlfn.IFNA(VLOOKUP(C27,Table1[],2,FALSE),"") -> #D9D9D9 | E27: Mixer | F27: Funcionales
A28: Path | B28: Modern And Innovative - 4.4% (33.7%) | C28: Kantar Blue | D28: =_xlfn.IFNA(VLOOKUP(C28,Table1[],2,FALSE),"") -> #0060FF | E28: Modern | F28: Posicionamiento
A29: Path | B29: Natural Ingredients - 1.6% (11.8%) | C29: Kantar Green | D29: =_xlfn.IFNA(VLOOKUP(C29,Table1[],2,FALSE),"") -> #00B600 | E29: Natural flavor | F29: Funcionales
A30: Path | B30: Natural Ingredients - 1.6% (11.8%) | C30: Kantar Green | D30: =_xlfn.IFNA(VLOOKUP(C30,Table1[],2,FALSE),"") -> #00B600 | E30: Natural ingredients | F30: Funcionales
A31: Path | B31: N/A | C31: Kantar Light Grey | D31: =_xlfn.IFNA(VLOOKUP(C31,Table1[],2,FALSE),"") -> #D9D9D9 | E31: Remember your childhood | F31: Emocional
A32: Path | B32: Balanced Recharge - 3.3% (23.5%) | C32: Kantar Magenta | D32: =_xlfn.IFNA(VLOOKUP(C32,Table1[],2,FALSE),"") -> #C700D3 | E32: Quenches thirst | F32: Funcionales
A33: Path | B33: Trusted And Reliable - 2.3% (29.8%) | C33: Kantar Sand | D33: =_xlfn.IFNA(VLOOKUP(C33,Table1[],2,FALSE),"") -> #AEAE9F | E33: It is popular | F33: Emocional
A34: Path | B34: Balanced Recharge - 3.3% (23.5%) | C34: Kantar Magenta | D34: =_xlfn.IFNA(VLOOKUP(C34,Table1[],2,FALSE),"") -> #C700D3 | E34: Recharges you with energy | F34: Funcionales
A35: Path | B35: Refreshing - 0.8% (5.8%) | C35: Kantar Red | D35: =_xlfn.IFNA(VLOOKUP(C35,Table1[],2,FALSE),"") -> #FA0028 | E35: Refreshing | F35: Funcionales
A36: Path | B36: N/A | C36: Kantar Light Grey | D36: =_xlfn.IFNA(VLOOKUP(C36,Table1[],2,FALSE),"") -> #D9D9D9 | E36: Related to moments of entertainment | F36: Ocasiones
A37: Path | B37: Trusted And Reliable - 2.3% (29.8%) | C37: Kantar Sand | D37: =_xlfn.IFNA(VLOOKUP(C37,Table1[],2,FALSE),"") -> #AEAE9F | E37: Reliable | F37: Emocional
... A48: Path | B48: Unique Irresistible Sensation - 2.1% (27.5%) | C48: Kantar Red | D48: =_xlfn.IFNA(VLOOKUP(C48,Table1[],2,FALSE),"") -> #FA0028 | E48: Stimulates your senses | F48: Emocional
A49: Tracking | B49: Convenient and attractive package - 4.1% (42.7%) | C49: Kantar Teal | D49: =_xlfn.IFNA(VLOOKUP(C49,Table1[],2,FALSE),"") -> #00E5BA | E49: Attractive packaging | F49: Activador | G49: Attractive packaging - 1.3% (32.6%)
A50: Tracking | B50: Convenient and attractive package - 4.1% (42.7%) | C50: Kantar Teal | D50: =_xlfn.IFNA(VLOOKUP(C50,Table1[],2,FALSE),"") -> #00E5BA | E50: Convenient presentations | F50: Activador | G50: Convenient presentations - 1.4% (33.7%)
A51: Tracking | B51: Accessible - 2.4% (24.3%) | C51: Kantar Purple | D51: =_xlfn.IFNA(VLOOKUP(C51,Table1[],2,FALSE),"") -> #802AB7 | E51: Easy to find | F51: Activador | G51: Easy to find - 1.2% (49.5%)
A52: Tracking | B52: Attractive deals and marketing appeal - 3.2% (33.0%) | C52: Kantar Blue | D52: =_xlfn.IFNA(VLOOKUP(C52,Table1[],2,FALSE),"") -> #0060FF | E52: Engaging advertising | F52: Activador | G52: Engaging advertising - 1.6% (50.4%)
A53: Tracking | B53: Accessible - 2.4% (24.3%) | C53: Kantar Purple | D53: =_xlfn.IFNA(VLOOKUP(C53,Table1[],2,FALSE),"") -> #802AB7 | E53: Fair value | F53: Activador | G53: Fair value - 1.2% (50.5%)
A54: Tracking | B54: Delicious quality - 3.9% (42.1%) | C54: Kantar Blue | D54: =_xlfn.IFNA(VLOOKUP(C54,Table1[],2,FALSE),"") -> #0060FF | E54: Flavor | F54: Funcionales | G54: Flavor - 1.4% (35.0%)
A55: Tracking | B55: For my daily routine - 1.5% (15.6%) | C55: Kantar Teal | D55: =_xlfn.IFNA(VLOOKUP(C55,Table1[],2,FALSE),"") -> #00E5BA | E55: For enjoying when I am alone | F55: Ocasiones | G55: For enjoying when I am alone - 0.8% (50.2%)
A56: Tracking | B56: For my daily routine - 1.5% (15.6%) | C56: Kantar Teal | D56: =_xlfn.IFNA(VLOOKUP(C56,Table1[],2,FALSE),"") -> #00E5BA | E56: For everyday | F56: Ocasiones | G56: For everyday - 0.8% (49.8%)
A57: Tracking | B57: For me to indulge - 6.1% (52.4%) | C57: Kantar Purple | D57: =_xlfn.IFNA(VLOOKUP(C57,Table1[],2,FALSE),"") -> #802AB7 | E57: For someone like me | F57: Posicionamiento | G57: For someone like me - 3.1% (49.8%)
A58: Tracking | B58: My fun rebellious childhood - 3.0% (38.8%) | C58: Kantar Blue | D58: =_xlfn.IFNA(VLOOKUP(C58,Table1[],2,FALSE),"") -> #0060FF | E58: Fun | F58: Emocional | G58: Fun - 0.8% (26.0%)
A59: Tracking | B59: My fun rebellious childhood - 3.0% (38.8%) | C59: Kantar Blue | D59: =_xlfn.IFNA(VLOOKUP(C59,Table1[],2,FALSE),"") -> #0060FF | E59: Rebellious irreverent style | F59: Emocional | G59: Rebellious irreverent style - 0.7% (24.5%)
A60: Tracking | B60: Relaxation - 1.3% (13.7%) | C60: Kantar Orange | D60: =_xlfn.IFNA(VLOOKUP(C60,Table1[],2,FALSE),"") -> #FF5000 | E60: Helps you relax your body and mind | F60: Funcionales | G60: Helps you relax your body and mind - 1.3% (100.0%)
...

Sheet H2OH BR VS AR
A1: FactorType | B1: FactorName | C1: NodeColor | D1: =VLOOKUP(C1,CATA!A:B,2,FALSE) -> HexColor | E1: Attribute | F1: Group | G1: Full ATT Label | H1: Path = Right | Q1: Factor | R1: Factor Label
A2: Path | B2: Accessible - 2.4% (24.3%) | C2: Kantar Purple | D2: =_xlfn.IFNA(VLOOKUP(C2,Table1[],2,FALSE),"") -> #802AB7 | E2: =LEFT(G2,FIND(" - ",G2)) -> Easy to find | F2: Activador | G2: Easy to find - 1.2% (49.5%) | H2: Tracking = Left | L2: =LEFT(B2,FIND(" - ",B2)-1) -> Accessible | M2: =VLOOKUP(L2,Q:R,2,FALSE) -> Accessible - 2.4% (24.3%) | Q2: Convenient and attractive package | R2: Convenient and attractive package - 4.1% (42.7%)
A3: Path | B3: Accessible - 2.4% (24.3%) | C3: Kantar Purple | D3: =_xlfn.IFNA(VLOOKUP(C3,Table1[],2,FALSE),"") -> #802AB7 | E3: =LEFT(G3,FIND(" - ",G3)) -> Fair value | F3: Activador | G3: Fair value - 1.2% (50.5%) | L3: =LEFT(B3,FIND(" - ",B3)-1) -> Accessible | M3: =VLOOKUP(L3,Q:R,2,FALSE) -> Accessible - 2.4% (24.3%) | Q3: Convenient and attractive package | R3: Convenient and attractive package - 4.1% (42.7%)
A4: Path | B4: Attractive deals and marketing appeal - 3.2% (33.0%) | C4: Kantar Blue | D4: =_xlfn.IFNA(VLOOKUP(C4,Table1[],2,FALSE),"") -> #0060FF | E4: =LEFT(G4,FIND(" - ",G4)) -> Engaging advertising | F4: Activador | G4: Engaging advertising - 1.6% (50.4%) | L4: =LEFT(B4,FIND(" - ",B4)-1) -> Attractive deals and marketing appeal | M4: =VLOOKUP(L4,Q:R,2,FALSE) -> Attractive deals and marketing appeal - 3.2% (33.0%) | Q4: Convenient and attractive package | R4: Convenient and attractive package - 4.1% (42.7%)
A5: Path | B5: Attractive deals and marketing appeal - 3.2% (33.0%) | C5: Kantar Blue | D5: =_xlfn.IFNA(VLOOKUP(C5,Table1[],2,FALSE),"") -> #0060FF | E5: =LEFT(G5,FIND(" - ",G5)) -> It has offers or promotions | F5: Activador | G5: It has offers or promotions - 1.6% (49.6%) | L5: =LEFT(B5,FIND(" - ",B5)-1) -> Attractive deals and marketing appeal | M5: =VLOOKUP(L5,Q:R,2,FALSE) -> Attractive deals and marketing appeal - 3.2% (33.0%) | Q5: Attractive deals and marketing appeal | R5: Attractive deals and marketing appeal - 3.2% (33.0%)
