Workbook

Sheet AVP
A1: g | B1: Period | C1: Observed | D1: Estimated | E1: Base | F1: Residual | G1: APE | I1: Model Stat | L1: Year | M1: Observed | N1: Estimated | O1: RSQ | P1: Total RSQ
A2: FY_2022 | B2: 44440 | C2: 3309.968 | D2: 3378.9217 | E2: 2486.3069 | F2: =C2-D2 -> -68.953714 | G2: =ABS(F2/C2) -> 0.020832139 | I2: RSQ | J2: 0.9055 | L2: FY_2021 | M2: =SUMIFS($C:$C,$A:$A,$L2) -> 0 | N2: =SUMIFS($D:$D,$A:$A,$L2) -> 0 | O2: =RSQ(C2:C38,D2:D38) -> 0.90549327 | P2: =RSQ(C2:C38,D2:D38) -> 0.90549327
A3: FY_2022 | B3: 44470 | C3: 3028.298 | D3: 2934.4873 | E3: 2472.805 | F3: =C3-D3 -> 93.810709 | G3: =ABS(F3/C3) -> 0.030978031 | I3: Adj Rsq | J3: 0.8209 | L3: FY_2022 | M3: =SUMIFS($C:$C,$A:$A,$L3) -> 33769.537 | N3: =SUMIFS($D:$D,$A:$A,$L3) -> 33568.271 | O3: =RSQ(C2:C13,D2:D13) -> 0.76986394
A4: FY_2022 | B4: 44501 | C4: 2525.561 | D4: 2703.1043 | E4: 2469.04 | F4: =C4-D4 -> -177.54328 | G4: =ABS(F4/C4) -> 0.070298552 | I4: Mape | J4: 0.0686 | L4: FY_2023 | M4: =SUMIFS($C:$C,$A:$A,$L4) -> 31283.97 | N4: =SUMIFS($D:$D,$A:$A,$L4) -> 31650.006 | O4: =RSQ(C14:C25,D14:D25) -> 0.90487683
A5: FY_2022 | B5: 44531 | C5: 2741.46 | D5: 2294.8618 | E5: 2447.4368 | F5: =C5-D5 -> 446.59825 | G5: =ABS(F5/C5) -> 0.16290526 | I5: DW | J5: 2.54 | L5: FY_2024 | M5: =SUMIFS($C:$C,$A:$A,$L5) -> 33662.95 | N5: =SUMIFS($D:$D,$A:$A,$L5) -> 33524.998 | O5: =RSQ(C26:C37,D26:D37) -> 0.93509263
A6: FY_2022 | B6: 44562 | C6: 2120.791 | D6: 2313.7008 | E6: 2469.8363 | F6: =C6-D6 -> -192.9098 | G6: =ABS(F6/C6) -> 0.090961251 | L6: Due to 23 vs 22 (12 Months) | M6: =M4/M3-1 -> -0.073603822 | N6: =N4/N3-1 -> -0.057145199
A7: FY_2022 | B7: 44593 | C7: 2025.474 | D7: 2423.8705 | E7: 2473.4603 | F7: =C7-D7 -> -398.39648 | G7: =ABS(F7/C7) -> 0.19669296 | L7: Due to 24 vs 23 (12 Months) | M7: =M5/M4-1 -> 0.076044696 | N7: =N5/N4-1 -> 0.059241462
A8: FY_2022 | B8: 44621 | C8: 2782.846 | D8: 2418.5679 | E8: 2439.2559 | F8: =C8-D8 -> 364.27812 | G8: =ABS(F8/C8) -> 0.13090128
A9: FY_2022 | B9: 44652 | C9: 2487.264 | D9: 2525.0552 | E9: 2438.6478 | F9: =C9-D9 -> -37.791168 | G9: =ABS(F9/C9) -> 0.015193871
A10: FY_2022 | B10: 44682 | C10: 3227.268 | D10: 3213.8703 | E10: 2434.8381 | F10: =C10-D10 -> 13.397744 | G10: =ABS(F10/C10) -> 0.0041514197
A11: FY_2022 | B11: 44713 | C11: 3720.315 | D11: 3627.6462 | E11: 2432.474 | F11: =C11-D11 -> 92.6688 | G11: =ABS(F11/C11) -> 0.024908859
A12: FY_2022 | B12: 44743 | C12: 2943.439 | D12: 2817.2819 | E12: 2437.3293 | F12: =C12-D12 -> 126.15708 | G12: =ABS(F12/C12) -> 0.042860436
A13: FY_2022 | B13: 44774 | C13: 2856.853 | D13: 2916.9034 | E13: 2451.2042 | F13: =C13-D13 -> -60.050363 | G13: =ABS(F13/C13) -> 0.02101976
A14: FY_2023 | B14: 44805 | C14: 3721.873 | D14: 3687.1325 | E14: 2460.6864 | F14: =C14-D14 -> 34.740544 | G14: =ABS(F14/C14) -> 0.0093341561
A15: FY_2023 | B15: 44835 | C15: 2659.504 | D15: 2840.6742 | E15: 2472.361 | F15: =C15-D15 -> -181.17022 | G15: =ABS(F15/C15) -> 0.068121809
A16: FY_2023 | B16: 44866 | C16: 2149.636 | D16: 2329.6368 | E16: 2471.2079 | F16: =C16-D16 -> -180.00079 | G16: =ABS(F16/C16) -> 0.083735474
A17: FY_2023 | B17: 44896 | C17: 2506.8 | D17: 2089.3193 | E17: 2458.2113 | F17: =C17-D17 -> 417.48072 | G17: =ABS(F17/C17) -> 0.1665393
A18: FY_2023 | B18: 44927 | C18: 1772.677 | D18: 1906.438 | E18: 2471.9961 | F18: =C18-D18 -> -133.76095 | G18: =ABS(F18/C18) -> 0.075457035
A19: FY_2023 | B19: 44958 | C19: 1399.56 | D19: 1650.4221 | E19: 2477.0791 | F19: =C19-D19 -> -250.86213 | G19: =ABS(F19/C19) -> 0.17924357
... A38: FY_2025 | B38: 45536 | C38: 4210.684 | D38: 4107.5456 | E38: 2444.9632 | F38: =C38-D38 -> 103.13841 | G38: =ABS(F38/C38) -> 0.024494454

Sheet Model Result
E1: Volume Contribution (in KG) | I1: Contribution % | M1: Due-to | O1: Revenue (in CLP) | S1: ROI | X1: Spends | AB1: Activity (Impressions, Clicks, GRPs, Search Index) | AF1: CPRP (Cost per Impressions/Click/GRP)
A2: Variable Name | B2: Spends | C2: Type | D2: Media Type | E2: Total | F2: FY_2022 | G2: FY_2023 | H2: FY_2024 | I2: Total | J2: FY_2022 | K2: FY_2023 | L2: FY_2024 | M2: FY23 vs FY22 (12 Months) | N2: FY24 vs FY23 (12 Months) | O2: Total | P2: FY_2022 | Q2: FY_2023 | R2: FY_2024 | S2: Total | T2: FY_2022 | U2: FY_2023 | V2: FY_2024 | W2: Change | X2: Total | Y2: FY_2022 | Z2: FY_2023 | AA2: FY_2024 | AB2: Total | AC2: FY_2022 | AD2: FY_2023 | AE2: FY_2024 | AF2: Total | AG2: FY_2022 | AH2: FY_2023 | AI2: FY_2024 | AJ2: Change
A3: Base | C3: Base | D3: Base | E3: {=IFERROR(HLOOKUP(A3,Decomposition!$G$1:$BB$43,{40,41,42,43},0),0)} -> 88765.075 | F3: 29452.635 | G3: 29748.318 | H3: 29564.123 | I3: =IFERROR(E3/SUM(E$3:E$22),0) -> 0.89894806 | J3: =IFERROR(F3/SUM(F$3:F$22),0) -> 0.87739504 | K3: =IFERROR(G3/SUM(G$3:G$22),0) -> 0.9399151 | L3: =IFERROR(H3/SUM(H$3:H$22),0) -> 0.88185307 | M3: =(G3-F3)/SUM(F$3:F$22) -> 0.0088084252 | N3: =(H3-G3)/SUM(G$3:G$22) -> -0.0058197644 | O3: {=IFERROR(HLOOKUP(A3,Decomposition!$BF$1:$BZ$43,{40,41,42,43},0),0)} -> 8.170997e+09 | P3: 2.5991958e+09 | Q3: 2.7541831e+09 | R3: 2.8176181e+09 | W3: =IFERROR(#REF!/T3-1,"") | AJ3: =IFERROR(AH3/AG3-1,"")
A4: Twinings_Price | C4: Twinings' Price | D4: Price | E4: {=IFERROR(HLOOKUP(A4,Decomposition!$G$1:$BB$43,{40,41,42,43},0),0)} -> -11484.703 | F4: -2409.3376 | G4: -6205.798 | H4: -2869.5675 | I4: =IFERROR(E4/SUM(E$3:E$22),0) -> -0.11630871 | J4: =IFERROR(F4/SUM(F$3:F$22),0) -> -0.071774255 | K4: =IFERROR(G4/SUM(G$3:G$22),0) -> -0.19607573 | L4: =IFERROR(H4/SUM(H$3:H$22),0) -> -0.085594858 | M4: =(G4-F4)/SUM(F$3:F$22) -> -0.11309669 | N4: =(H4-G4)/SUM(G$3:G$22) -> 0.10541011 | O4: {=IFERROR(HLOOKUP(A4,Decomposition!$BF$1:$BZ$43,{40,41,42,43},0),0)} -> -1.053808e+09 | P4: -2.0679123e+08 | Q4: -5.7441182e+08 | R4: -2.7260493e+08 | W4: =IFERROR(#REF!/T4-1,"") | AJ4: =IFERROR(AH4/AG4-1,"")
A5: Competitor_Price | C5: Competitors' Price | D5: Price | E5: {=IFERROR(HLOOKUP(A5,Decomposition!$G$1:$BB$43,{40,41,42,43},0),0)} -> 8556.7858 | F5: 1026.7715 | G5: 3222.3833 | H5: 4307.631 | I5: =IFERROR(E5/SUM(E$3:E$22),0) -> 0.086656897 | J5: =IFERROR(F5/SUM(F$3:F$22),0) -> 0.03058756 | K5: =IFERROR(G5/SUM(G$3:G$22),0) -> 0.10181304 | L5: =IFERROR(H5/SUM(H$3:H$22),0) -> 0.12849012 | M5: =(G5-F5)/SUM(F$3:F$22) -> 0.065407354 | N5: =(H5-G5)/SUM(G$3:G$22) -> 0.034289022 | O5: {=IFERROR(HLOOKUP(A5,Decomposition!$BF$1:$BZ$43,{40,41,42,43},0),0)} -> 8.0216579e+08 | P5: 92837964 | Q5: 2.9830993e+08 | R5: 4.110179e+08 | W5: =IFERROR(#REF!/T5-1,"") | AJ5: =IFERROR(AH5/AG5-1,"")
A6: Twinings_WD | C6: Twinings' Distribution | D6: Distribution | E6: {=IFERROR(HLOOKUP(A6,Decomposition!$G$1:$BB$43,{40,41,42,43},0),0)} -> 9366.052 | F6: 3370.9159 | G6: 1964.0368 | H6: 4031.0994 | I6: =IFERROR(E6/SUM(E$3:E$22),0) -> 0.094852556 | J6: =IFERROR(F6/SUM(F$3:F$22),0) -> 0.1004197 | K6: =IFERROR(G6/SUM(G$3:G$22),0) -> 0.062054863 | L6: =IFERROR(H6/SUM(H$3:H$22),0) -> 0.1202416 | M6: =(G6-F6)/SUM(F$3:F$22) -> -0.041910979 | N6: =(H6-G6)/SUM(G$3:G$22) -> 0.065310023 | O6: {=IFERROR(HLOOKUP(A6,Decomposition!$BF$1:$BZ$43,{40,41,42,43},0),0)} -> 8.6580008e+08 | P6: 2.9909529e+08 | Q6: 1.8114113e+08 | R6: 3.8556365e+08 | W6: =IFERROR(#REF!/T6-1,"") | AJ6: =IFERROR(AH6/AG6-1,"")
A7: Competitor_WD | C7: Competitors' Distribution | D7: Distribution | E7: {=IFERROR(HLOOKUP(A7,Decomposition!$G$1:$BB$43,{40,41,42,43},0),0)} -> -4392.7024 | F7: -948.99476 | G7: -911.16153 | H7: -2532.5461 | I7: =IFERROR(E7/SUM(E$3:E$22),0) -> -0.044486091 | J7: =IFERROR(F7/SUM(F$3:F$22),0) -> -0.028270588 | K7: =IFERROR(G7/SUM(G$3:G$22),0) -> -0.028788669 | L7: =IFERROR(H7/SUM(H$3:H$22),0) -> -0.07554202 | M7: =(G7-F7)/SUM(F$3:F$22) -> 0.0011270533 | N7: =(H7-G7)/SUM(G$3:G$22) -> -0.05122857 | O7: {=IFERROR(HLOOKUP(A7,Decomposition!$BF$1:$BZ$43,{40,41,42,43},0),0)} -> -4.1014827e+08 | P7: -84294846 | Q7: -84417543 | R7: -2.4143588e+08 | S7: =IFERROR(#REF!/P7-1,"") | T7: =IFERROR(#REF!/Q7-1,"") | U7: =IFERROR(#REF!/R7-1,"") | V7: =IFERROR(#REF!/S7-1,"") | W7: =IFERROR(#REF!/T7-1,"") | X7: {=IFERROR(HLOOKUP($B7,'Raw Data'!$F$1:$AI$43,{40,41,42,43},0),"")} | AM7: inversion | AR7: Contribucion
A8: Discounts_5%_Min | C8: Discount | D8: Discount | E8: {=IFERROR(HLOOKUP(A8,Decomposition!$G$1:$BB$43,{40,41,42,43},0),0)} -> 8683.6671 | F8: 3531.7831 | G8: 4071.3611 | H8: 1080.5228 | I8: =IFERROR(E8/SUM(E$3:E$22),0) -> 0.087941858 | J8: =IFERROR(F8/SUM(F$3:F$22),0) -> 0.10521195 | K8: =IFERROR(G8/SUM(G$3:G$22),0) -> 0.12863698 | L8: =IFERROR(H8/SUM(H$3:H$22),0) -> 0.032230362 | M8: =(G8-F8)/SUM(F$3:F$22) -> 0.016074048 | N8: =(H8-G8)/SUM(G$3:G$22) -> -0.094497244 | O8: {=IFERROR(HLOOKUP(A8,Decomposition!$BF$1:$BZ$43,{40,41,42,43},0),0)} -> 7.6799676e+08 | P8: 2.9993542e+08 | Q8: 3.6808757e+08 | R8: 99973766 | S8: =IFERROR(#REF!/P8-1,"") | T8: =IFERROR(#REF!/Q8-1,"") | U8: =IFERROR(#REF!/R8-1,"") | V8: =IFERROR(#REF!/S8-1,"") | W8: =IFERROR(#REF!/T8-1,"") | X8: {=IFERROR(HLOOKUP($B8,'Raw Data'!$F$1:$AI$43,{40,41,42,43},0),"")} | AM8: Total | AN8: FY_2022 | AO8: FY_2023 | AP8: FY_2024 | AR8: Total | AS8: FY_2022 | AT8: FY_2023 | AU8: FY_2024
A9: YouTube_FB_Impressions | B9: YouTube_FB_Spends | C9: Media | D9: Digital | E9: {=IFERROR(HLOOKUP(A9,Decomposition!$G$1:$BB$43,{40,41,42,43},0),0)} -> 3861.6138 | F9: 4.9790663e-07 | G9: 1179.903 | H9: 2681.7108 | I9: =IFERROR(E9/SUM(E$3:E$22),0) -> 0.039107613 | J9: =IFERROR(F9/SUM(F$3:F$22),0) -> 1.4832656e-11 | K9: =IFERROR(G9/SUM(G$3:G$22),0) -> 0.03727971 | L9: =IFERROR(H9/SUM(H$3:H$22),0) -> 0.079991377 | M9: =(G9-F9)/SUM(F$3:F$22) -> 0.035149353 | N9: =(H9-G9)/SUM(G$3:G$22) -> 0.047450473 | O9: {=IFERROR(HLOOKUP(A9,Decomposition!$BF$1:$BZ$43,{40,41,42,43},0),0)} -> 3.6464638e+08 | P9: 0.04387661 | Q9: 1.0779671e+08 | R9: 2.5684967e+08 | S9: =IFERROR(O9/X9,0) -> 1.9471255 | T9: =IFERROR(P9/Y9,0) -> 0 | U9: =IFERROR(Q9/Z9,0) -> 2.1526666 | V9: =IFERROR(R9/AA9,0) -> 1.8721053 | W9: =IFERROR(V9/U9,0) -> 0.86966798 | X9: {=IFERROR(HLOOKUP($B9,'Raw Data'!$F$1:$AX$43,{40,41,42,43},0),"")} -> 1.872742e+08 | Y9: 0 | Z9: 50075894 | AA9: 1.3719831e+08 | AB9: {=IFERROR(HLOOKUP($A9,'Raw Data'!$F$1:$AX$43,{40,41,42,43},0),"")} -> 269644723 | AC9: 0 | AD9: 78297126 | AE9: 191347597 | AF9: =IFERROR(X9/AB9,0) -> 0.69452204 | AG9: =IFERROR(Y9/AC9,0) -> 0 | AH9: =IFERROR(Z9/AD9,0) -> 0.63956235 | AI9: =IFERROR(AA9/AE9,0) -> 0.71701088 | AJ9: =IFERROR(AI9/AH9,0) -> 1.1210961 | AM9: =IFERROR(X9/SUM(X$9:X$13),0) -> 0.5930052 | AN9: =IFERROR(Y9/SUM(Y$9:Y$13),0) -> 0 | AO9: =IFERROR(Z9/SUM(Z$9:Z$13),0) -> 0.35880244 | AP9: =IFERROR(AA9/SUM(AA$9:AA$13),0) -> 0.77846831 | AR9: =IFERROR(I9/SUM(I$9:I$13),0) -> 0.48704591 | AS9: 0 | AT9: =IFERROR(K9/SUM(K$9:K$13),0) -> 0.36555662 | AU9: =IFERROR(L9/SUM(L$9:L$13),0) -> 0.57046078 | AW9: =IFERROR(AR9/AM9*100,"") -> 82.13181 | AX9: =IFERROR(AS9/AN9*100,"") | AY9: =IFERROR(AT9/AO9*100,"") -> 101.88243 | AZ9: =IFERROR(AU9/AP9*100,"") -> 73.279897
A10: Google_Search_Clicks | B10: Google_Search_Spends | C10: Media | D10: Digital | E10: {=IFERROR(HLOOKUP(A10,Decomposition!$G$1:$BB$43,{40,41,42,43},0),0)} -> 583.09361 | F10: 2.7099364e-07 | G10: 357.71739 | H10: 225.37621 | I10: =IFERROR(E10/SUM(E$3:E$22),0) -> 0.0059051476 | J10: =IFERROR(F10/SUM(F$3:F$22),0) -> 8.0729102e-12 | K10: =IFERROR(G10/SUM(G$3:G$22),0) -> 0.011302285 | L10: =IFERROR(H10/SUM(H$3:H$22),0) -> 0.0067226317 | M10: =(G10-F10)/SUM(F$3:F$22) -> 0.010656414 | N10: =(H10-G10)/SUM(G$3:G$22) -> -0.0041813951 | O10: {=IFERROR(HLOOKUP(A10,Decomposition!$BF$1:$BZ$43,{40,41,42,43},0),0)} -> 54442988 | P10: 0.023881322 | Q10: 32690641 | R10: 21752346 | S10: =IFERROR(O10/X10,0) -> 3.9220144 | T10: =IFERROR(P10/Y10,0) -> 0 | U10: =IFERROR(Q10/Z10,0) -> 4.6619312 | V10: =IFERROR(R10/AA10,0) -> 3.166681 | W10: =IFERROR(V10/U10,0) -> 0.67926376 | X10: {=IFERROR(HLOOKUP($B10,'Raw Data'!$F$1:$AX$43,{40,41,42,43},0),"")} -> 13881384 | Y10: 0 | Z10: 7012253 | AA10: 6869131 | AB10: {=IFERROR(HLOOKUP($A10,'Raw Data'!$F$1:$AX$43,{40,41,42,43},0),"")} -> 101654 | AC10: 0 | AD10: 60335 | AE10: 41319 | AF10: =IFERROR(X10/AB10,0) -> 136.55522 | AG10: =IFERROR(Y10/AC10,0) -> 0 | AH10: =IFERROR(Z10/AD10,0) -> 116.22198 | AI10: =IFERROR(AA10/AE10,0) -> 166.2463 | AJ10: =IFERROR(AI10/AH10,0) -> 1.4304205 | AM10: =IFERROR(X10/SUM(X$9:X$13),0) -> 0.043955509 | AN10: =IFERROR(Y10/SUM(Y$9:Y$13),0) -> 0 | AO10: =IFERROR(Z10/SUM(Z$9:Z$13),0) -> 0.050244005 | AP10: =IFERROR(AA10/SUM(AA$9:AA$13),0) -> 0.038975705 | AR10: =IFERROR(I10/SUM(I$9:I$13),0) -> 0.073542662 | AS10: 0 | AT10: =IFERROR(K10/SUM(K$9:K$13),0) -> 0.11082772 | AU10: =IFERROR(L10/SUM(L$9:L$13),0) -> 0.047942639 | AW10: =IFERROR(AR10/AM10*100,"") -> 167.31159 | AX10: =IFERROR(AS10/AN10*100,"") | AY10: =IFERROR(AT10/AO10*100,"") -> 220.579 | AZ10: =IFERROR(AU10/AP10*100,"") -> 123.00647
A11: Display_Impressions | B11: Display_Spends | C11: Media | D11: Digital | E11: {=IFERROR(HLOOKUP(A11,Decomposition!$G$1:$BB$43,{40,41,42,43},0),0)} -> 1054.2437 | F11: 4.1377384e-07 | G11: 801.47445 | H11: 252.76922 | I11: =IFERROR(E11/SUM(E$3:E$22),0) -> 0.010676612 | J11: =IFERROR(F11/SUM(F$3:F$22),0) -> 1.2326338e-11 | K11: =IFERROR(G11/SUM(G$3:G$22),0) -> 0.025323043 | L11: =IFERROR(H11/SUM(H$3:H$22),0) -> 0.0075397237 | M11: =(G11-F11)/SUM(F$3:F$22) -> 0.023875953 | N11: =(H11-G11)/SUM(G$3:G$22) -> -0.017336655 | O11: {=IFERROR(HLOOKUP(A11,Decomposition!$BF$1:$BZ$43,{40,41,42,43},0),0)} -> 96765547 | P11: 0.036507686 | Q11: 73223482 | R11: 23542064 | S11: =IFERROR(O11/X11,0) -> 5.2662044 | T11: =IFERROR(P11/Y11,0) -> 0 | U11: =IFERROR(Q11/Z11,0) -> 3.9849909 | V11: =IFERROR(R11/AA11,0) -> 0 | W11: =IFERROR(V11/U11,0) -> 0 | X11: {=IFERROR(HLOOKUP($B11,'Raw Data'!$F$1:$AX$43,{40,41,42,43},0),"")} -> 18374818 | Y11: 0 | Z11: 18374818 | AA11: 0 | AB11: {=IFERROR(HLOOKUP($A11,'Raw Data'!$F$1:$AX$43,{40,41,42,43},0),"")} -> 3532942 | AC11: 0 | AD11: 3532942 | AE11: 0 | AF11: =IFERROR(X11/AB11,0) -> 5.2009962 | AG11: =IFERROR(Y11/AC11,0) -> 0 | AH11: =IFERROR(Z11/AD11,0) -> 5.2009962 | AI11: =IFERROR(AA11/AE11,0) -> 0 | AJ11: =IFERROR(AI11/AH11,0) -> 0 | AM11: =IFERROR(X11/SUM(X$9:X$13),0) -> 0.058184003 | AN11: =IFERROR(Y11/SUM(Y$9:Y$13),0) -> 0 | AO11: =IFERROR(Z11/SUM(Z$9:Z$13),0) -> 0.13165875 | AP11: =IFERROR(AA11/SUM(AA$9:AA$13),0) -> 0 | AR11: =IFERROR(I11/SUM(I$9:I$13),0) -> 0.13296645 | AS11: 0 | AT11: =IFERROR(K11/SUM(K$9:K$13),0) -> 0.24831218 | AU11: =IFERROR(L11/SUM(L$9:L$13),0) -> 0.053769754 | AW11: =IFERROR(AR11/AM11*100,"") -> 228.5275 | AX11: =IFERROR(AS11/AN11*100,"") | AY11: =IFERROR(AT11/AO11*100,"") -> 188.60288 | AZ11: =IFERROR(AU11/AP11*100,"")
A12: OOH_Screen_GRPs | B12: OOH_Screen_Spends | C12: Media | D12: OOH | E12: {=IFERROR(HLOOKUP(A12,Decomposition!$G$1:$BB$43,{40,41,42,43},0),0)} -> 1227.3599 | F12: 3.002175e-07 | G12: 658.46213 | H12: 568.8978 | I12: =IFERROR(E12/SUM(E$3:E$22),0) -> 0.012429808 | J12: =IFERROR(F12/SUM(F$3:F$22),0) -> 8.9434902e-12 | K12: =IFERROR(G12/SUM(G$3:G$22),0) -> 0.020804487 | L12: =IFERROR(H12/SUM(H$3:H$22),0) -> 0.016969361 | M12: =(G12-F12)/SUM(F$3:F$22) -> 0.01961561 | N12: =(H12-G12)/SUM(G$3:G$22) -> -0.0028298362 | O12: {=IFERROR(HLOOKUP(A12,Decomposition!$BF$1:$BZ$43,{40,41,42,43},0),0)} -> 1.1363705e+08 | P12: 0.026589881 | Q12: 60149267 | R12: 53487786 | S12: =IFERROR(O12/X12,0) -> 2.4934118 | T12: =IFERROR(P12/Y12,0) -> 0 | U12: =IFERROR(Q12/Z12,0) -> 1.3197887 | V12: =IFERROR(R12/AA12,0) -> 0 | W12: =IFERROR(V12/U12,0) -> 0 | X12: {=IFERROR(HLOOKUP($B12,'Raw Data'!$F$1:$AX$43,{40,41,42,43},0),"")} -> 45574923 | Y12: 0 | Z12: 45574923 | AA12: 0 | AB12: {=IFERROR(HLOOKUP($A12,'Raw Data'!$F$1:$AX$43,{40,41,42,43},0),"")} -> 460.11573 | AC12: 0 | AD12: 460.11573 | AE12: 0 | AF12: =IFERROR(X12/AB12,0) -> 99050.999 | AG12: =IFERROR(Y12/AC12,0) -> 0 | AH12: =IFERROR(Z12/AD12,0) -> 99050.999 | AI12: =IFERROR(AA12/AE12,0) -> 0 | AJ12: =IFERROR(AI12/AH12,0) -> 0 | AM12: =IFERROR(X12/SUM(X$9:X$13),0) -> 0.14431334 | AN12: =IFERROR(Y12/SUM(Y$9:Y$13),0) -> 0 | AO12: =IFERROR(Z12/SUM(Z$9:Z$13),0) -> 0.3265522 | AP12: =IFERROR(AA12/SUM(AA$9:AA$13),0) -> 0 | AR12: =IFERROR(I12/SUM(I$9:I$13),0) -> 0.15480073 | AS12: 0 | AT12: =IFERROR(K12/SUM(K$9:K$13),0) -> 0.20400422 | AU12: =IFERROR(L12/SUM(L$9:L$13),0) -> 0.12101748 | AW12: =IFERROR(AR12/AM12*100,"") -> 107.26709 | AX12: =IFERROR(AS12/AN12*100,"") | AY12: =IFERROR(AT12/AO12*100,"") -> 62.472162 | AZ12: =IFERROR(AU12/AP12*100,"")
A13: OOH_Retail_GRPs | B13: OOH_Retail_Spends | C13: Media | D13: OOH | E13: {=IFERROR(HLOOKUP(A13,Decomposition!$G$1:$BB$43,{40,41,42,43},0),0)} -> 1202.3334 | F13: 5.5575132e-08 | G13: 230.1318 | H13: 972.20156 | I13: =IFERROR(E13/SUM(E$3:E$22),0) -> 0.012176357 | J13: =IFERROR(F13/SUM(F$3:F$22),0) -> 1.6555852e-12 | K13: =IFERROR(G13/SUM(G$3:G$22),0) -> 0.0072711457 | L13: =IFERROR(H13/SUM(H$3:H$22),0) -> 0.028999302 | M13: =(G13-F13)/SUM(F$3:F$22) -> 0.0068556346 | N13: =(H13-G13)/SUM(G$3:G$22) -> 0.023446118 | O13: {=IFERROR(HLOOKUP(A13,Decomposition!$BF$1:$BZ$43,{40,41,42,43},0),0)} -> 1.1363163e+08 | P13: 0.0049364765 | Q13: 21042717 | R13: 92588915 | S13: =IFERROR(O13/X13,0) -> 2.2412551 | T13: =IFERROR(P13/Y13,0) -> 0 | U13: =IFERROR(Q13/Z13,0) -> 1.1358425 | V13: =IFERROR(R13/AA13,0) -> 2.8777636 | W13: =IFERROR(V13/U13,0) -> 2.5335938 | X13: {=IFERROR(HLOOKUP($B13,'Raw Data'!$F$1:$AX$43,{40,41,42,43},0),"")} -> 50700000 | Y13: 0 | Z13: 18526087 | AA13: 32173913 | AB13: {=IFERROR(HLOOKUP($A13,'Raw Data'!$F$1:$AX$43,{40,41,42,43},0),"")} -> 287.88743 | AC13: 0 | AD13: 187.03583 | AE13: 100.8516 | AF13: =IFERROR(X13/AB13,0) -> 176110.5 | AG13: =IFERROR(Y13/AC13,0) -> 0 | AH13: =IFERROR(Z13/AD13,0) -> 99051.003 | AI13: =IFERROR(AA13/AE13,0) -> 319022.33 | AJ13: =IFERROR(AI13/AH13,0) -> 3.2207885 | AM13: =IFERROR(X13/SUM(X$9:X$13),0) -> 0.16054194 | AN13: =IFERROR(Y13/SUM(Y$9:Y$13),0) -> 0 | AO13: =IFERROR(Z13/SUM(Z$9:Z$13),0) -> 0.13274261 | AP13: =IFERROR(AA13/SUM(AA$9:AA$13),0) -> 0.18255598 | AR13: =IFERROR(I13/SUM(I$9:I$13),0) -> 0.15164425 | AS13: 0 | AT13: =IFERROR(K13/SUM(K$9:K$13),0) -> 0.071299253 | AU13: =IFERROR(L13/SUM(L$9:L$13),0) -> 0.20680935 | AW13: =IFERROR(AR13/AM13*100,"") -> 94.457719 | AX13: =IFERROR(AS13/AN13*100,"") | AY13: =IFERROR(AT13/AO13*100,"") -> 53.712408 | AZ13: =IFERROR(AU13/AP13*100,"") -> 113.28544
A14: Competitor_GRPs | B14: Competitor_Spends | C14: Competitors Media | D14: Comp TV | E14: {=IFERROR(HLOOKUP(A14,Decomposition!$G$1:$BB$43,{40,41,42,43},0),0)} -> -2484.2791 | F14: -552.81997 | G14: -760.90258 | H14: -1170.5565 | I14: =IFERROR(E14/SUM(E$3:E$22),0) -> -0.02515897 | J14: =IFERROR(F14/SUM(F$3:F$22),0) -> -0.016468527 | K14: =IFERROR(G14/SUM(G$3:G$22),0) -> -0.024041151 | L14: =IFERROR(H14/SUM(H$3:H$22),0) -> -0.034915932 | M14: =(G14-F14)/SUM(F$3:F$22) -> -0.0061987884 | N14: =(H14-G14)/SUM(G$3:G$22) -> -0.012943251 | O14: {=IFERROR(HLOOKUP(A14,Decomposition!$BF$1:$BZ$43,{40,41,42,43},0),0)} -> -2.2940367e+08 | P14: -48310261 | Q14: -69475883 | R14: -1.1161753e+08 | W14: =IFERROR(#REF!/T14-1,"") | AJ14: =IFERROR(AI14/AH14,0) -> 0
A15: Inflation | C15: External Factors | D15: External | E15: {=IFERROR(HLOOKUP(A15,Decomposition!$G$1:$BB$43,{40,41,42,43},0),0)} -> -2721.4789 | F15: -1564.8985 | G15: -597.69937 | H15: -558.88099 | I15: =IFERROR(E15/SUM(E$3:E$22),0) -> -0.027561157 | J15: =IFERROR(F15/SUM(F$3:F$22),0) -> -0.046618384 | K15: =IFERROR(G15/SUM(G$3:G$22),0) -> -0.018884653 | L15: =IFERROR(H15/SUM(H$3:H$22),0) -> -0.016670575 | M15: =(G15-F15)/SUM(F$3:F$22) -> 0.028812898 | N15: =(H15-G15)/SUM(G$3:G$22) -> 0.0012264889 | O15: {=IFERROR(HLOOKUP(A15,Decomposition!$BF$1:$BZ$43,{40,41,42,43},0),0)} -> -2.4686958e+08 | P15: -1.3836807e+08 | Q15: -54819984 | R15: -53681532 | W15: =IFERROR(#REF!/T15-1,"") | AJ15: =IFERROR(AH15/AG15-1,"")
A16: Temperature | C16: External Factors | D16: External | E16: {=IFERROR(HLOOKUP(A16,Decomposition!$G$1:$BB$43,{40,41,42,43},0),0)} -> -11897.195 | F16: -3749.1081 | G16: -4011.1989 | H16: -4136.8876 | I16: =IFERROR(E16/SUM(E$3:E$22),0) -> -0.12048613 | J16: =IFERROR(F16/SUM(F$3:F$22),0) -> -0.11168606 | K16: =IFERROR(G16/SUM(G$3:G$22),0) -> -0.12673612 | L16: =IFERROR(H16/SUM(H$3:H$22),0) -> -0.1233971 | M16: =(G16-F16)/SUM(F$3:F$22) -> -0.0078076955 | N16: =(H16-G16)/SUM(G$3:G$22) -> -0.0039712043 | O16: {=IFERROR(HLOOKUP(A16,Decomposition!$BF$1:$BZ$43,{40,41,42,43},0),0)} -> -1.0965518e+09 | P16: -3.2875377e+08 | Q16: -3.7524306e+08 | R16: -3.9255492e+08
A17: Covid_Index | C17: External Factors | D17: External | E17: {=IFERROR(HLOOKUP(A17,Decomposition!$G$1:$BB$43,{40,41,42,43},0),0)} -> 5102.9572 | F17: 4296.9998 | G17: 805.95741 | H17: 0 | I17: =IFERROR(E17/SUM(E$3:E$22),0) -> 0.051679035 | J17: =IFERROR(F17/SUM(F$3:F$22),0) -> 0.12800778 | K17: =IFERROR(G17/SUM(G$3:G$22),0) -> 0.025464685 | L17: =IFERROR(H17/SUM(H$3:H$22),0) -> 0 | M17: =(G17-F17)/SUM(F$3:F$22) -> -0.10399828 | N17: =(H17-G17)/SUM(G$3:G$22) -> -0.025464685 | O17: {=IFERROR(HLOOKUP(A17,Decomposition!$BF$1:$BZ$43,{40,41,42,43},0),0)} -> 4.5121725e+08 | P17: 3.786588e+08 | Q17: 72558453 | R17: 0
A18: Winter_Solstice | C18: External Factors | D18: External | E18: {=IFERROR(HLOOKUP(A18,Decomposition!$G$1:$BB$43,{40,41,42,43},0),0)} -> 1770.1362 | F18: 595.78993 | G18: 585.17521 | H18: 589.17107 | I18: =IFERROR(E18/SUM(E$3:E$22),0) -> 0.017926651 | J18: =IFERROR(F18/SUM(F$3:F$22),0) -> 0.017748603 | K18: =IFERROR(G18/SUM(G$3:G$22),0) -> 0.018488945 | L18: =IFERROR(H18/SUM(H$3:H$22),0) -> 0.017574082 | M18: =(G18-F18)/SUM(F$3:F$22) -> -0.00031621288 | N18: =(H18-G18)/SUM(G$3:G$22) -> 0.00012625155 | O18: {=IFERROR(HLOOKUP(A18,Decomposition!$BF$1:$BZ$43,{40,41,42,43},0),0)} -> 1.6597822e+08 | P18: 55836806 | Q18: 53203741 | R18: 56937673
A19: Independence_Month | C19: External Factors | D19: External | E19: {=IFERROR(HLOOKUP(A19,Decomposition!$G$1:$BB$43,{40,41,42,43},0),0)} -> 1550.3151 | F19: 518.53543 | G19: 511.84527 | H19: 519.93445 | I19: =IFERROR(E19/SUM(E$3:E$22),0) -> 0.015700463 | J19: =IFERROR(F19/SUM(F$3:F$22),0) -> 0.015447189 | K19: =IFERROR(G19/SUM(G$3:G$22),0) -> 0.016172044 | L19: =IFERROR(H19/SUM(H$3:H$22),0) -> 0.015508858 | M19: =(G19-F19)/SUM(F$3:F$22) -> -0.00019930016 | N19: =(H19-G19)/SUM(G$3:G$22) -> 0.00025558228 | O19: {=IFERROR(HLOOKUP(A19,Decomposition!$BF$1:$BZ$43,{40,41,42,43},0),0)} -> 1.3419586e+08 | P19: 42040638 | Q19: 43782135 | R19: 48373086
A23: *Consists of Dilmah, Lipton, Supremo, Te Club Prices | F23: =SUM(F3:F19) -> 33568.271 | G23: =SUM(G3:G19) -> 31650.006 | H23: =SUM(H3:H19) -> 33524.998
A24: **Consists of Dilmah and Te Club WD | G24: =G23/F23-1 -> -0.057145199 | H24: =H23/G23-1 -> 0.059241462 | I24: =MEDIAN(I9:I13) -> 0.012176357 | S24: =MEDIAN(S9:S13) -> 2.4934118
A25: ***Consists of TV GRPs of Supremo, Te Club, and Lipton | H25: =H23/F23 -> 0.9987109
E26: Volume Contribution (in KG) | I26: Contribution % | M26: Due-to | O26: Revenue (in CLP) | S26: ROI | X26: Spends | AB26: Activity (Impressions, Clicks, GRPs, Search Index) | AF26: CPRP (Cost per Impressions/Click/GRP)
C27: Type | D27: Media Type | E27: Total | F27: FY_2022 | G27: FY_2023 | H27: FY_2024 | I27: Total | J27: FY_2022 | K27: FY_2023 | L27: FY_2024 | M27: FY23 vs FY22 (12 Months) | N27: FY24 vs FY23 (12 Months) | O27: Total | P27: FY_2022 | Q27: FY_2023 | R27: FY_2024 | S27: Total | T27: FY_2022 | U27: FY_2023 | V27: FY_2024 | W27: Change | X27: Total | Y27: FY_2022 | Z27: FY_2023 | AA27: FY_2024 | AB27: Total | AC27: FY_2022 | AD27: FY_2023 | AE27: FY_2024 | AF27: Total | AG27: FY_2022 | AH27: FY_2023 | AI27: FY_2024 | AJ27: Change
C28: Base | D28: Base | E28: =SUMIFS(E$3:E$22,$C$3:$C$22,$C28,$D$3:$D$22,$D28) -> 88765.075 | F28: =SUMIFS(F$3:F$22,$C$3:$C$22,$C28,$D$3:$D$22,$D28) -> 29452.635 | G28: =SUMIFS(G$3:G$22,$C$3:$C$22,$C28,$D$3:$D$22,$D28) -> 29748.318 | H28: =SUMIFS(H$3:H$22,$C$3:$C$22,$C28,$D$3:$D$22,$D28) -> 29564.123 | I28: =E28/SUM(E$3:E$22) -> 0.89894806 | J28: =F28/SUM(F$3:F$22) -> 0.87739504 | K28: =G28/SUM(G$3:G$22) -> 0.9399151 | L28: =H28/SUM(H$3:H$22) -> 0.88185307 | M28: =(G28-F28)/SUM($F$3:$F$22) -> 0.0088084252 | N28: =(H28-G28)/SUM($G$3:$G$22) -> -0.0058197644 | O28: =SUMIFS(O$3:O$22,$C$3:$C$22,$C28,$D$3:$D$22,$D28) -> 8.170997e+09 | P28: =SUMIFS(P$3:P$22,$C$3:$C$22,$C28,$D$3:$D$22,$D28) -> 2.5991958e+09 | Q28: =SUMIFS(Q$3:Q$22,$C$3:$C$22,$C28,$D$3:$D$22,$D28) -> 2.7541831e+09 | R28: =SUMIFS(R$3:R$22,$C$3:$C$22,$C28,$D$3:$D$22,$D28) -> 2.8176181e+09 | X28: =SUMIFS(X$3:X$22,$C$3:$C$22,$C28,$D$3:$D$22,$D28) -> 0 | Y28: =SUMIFS(Y$3:Y$22,$C$3:$C$22,$C28,$D$3:$D$22,$D28) -> 0 | Z28: =SUMIFS(Z$3:Z$22,$C$3:$C$22,$C28,$D$3:$D$22,$D28) -> 0 | AA28: =SUMIFS(AA$3:AA$22,$C$3:$C$22,$C28,$D$3:$D$22,$D28) -> 0 | AB28: =SUMIFS(AB$3:AB$22,$C$3:$C$22,$C28,$D$3:$D$22,$D28) -> 0 | AC28: =SUMIFS(AC$3:AC$22,$C$3:$C$22,$C28,$D$3:$D$22,$D28) -> 0 | AD28: =SUMIFS(AD$3:AD$22,$C$3:$C$22,$C28,$D$3:$D$22,$D28) -> 0 | AE28: =SUMIFS(AE$3:AE$22,$C$3:$C$22,$C28,$D$3:$D$22,$D28) -> 0 | AF28: =IFERROR(X28/AB28,0) -> 0 | AG28: =IFERROR(Y28/AC28,0) -> 0 | AH28: =IFERROR(Z28/AD28,0) -> 0 | AI28: =IFERROR(AA28/AE28,0) -> 0 | AJ28: =IFERROR(AH28/AG28-1,"")
C29: Price | D29: Price | E29: =SUMIFS(E$3:E$22,$C$3:$C$22,$C29,$D$3:$D$22,$D29) -> 0 | F29: =SUMIFS(F$3:F$22,$C$3:$C$22,$C29,$D$3:$D$22,$D29) -> 0 | G29: =SUMIFS(G$3:G$22,$C$3:$C$22,$C29,$D$3:$D$22,$D29) -> 0 | H29: =SUMIFS(H$3:H$22,$C$3:$C$22,$C29,$D$3:$D$22,$D29) -> 0 | I29: =E29/SUM(E$3:E$22) -> 0 | J29: =F29/SUM(F$3:F$22) -> 0 | K29: =G29/SUM(G$3:G$22) -> 0 | L29: =H29/SUM(H$3:H$22) -> 0 | M29: =(G29-F29)/SUM($F$3:$F$22) -> 0 | N29: =(H29-G29)/SUM($G$3:$G$22) -> 0 | O29: =SUMIFS(O$3:O$22,$C$3:$C$22,$C29,$D$3:$D$22,$D29) -> 0 | P29: =SUMIFS(P$3:P$22,$C$3:$C$22,$C29,$D$3:$D$22,$D29) -> 0 | Q29: =SUMIFS(Q$3:Q$22,$C$3:$C$22,$C29,$D$3:$D$22,$D29) -> 0 | R29: =SUMIFS(R$3:R$22,$C$3:$C$22,$C29,$D$3:$D$22,$D29) -> 0 | X29: =SUMIFS(X$3:X$22,$C$3:$C$22,$C29,$D$3:$D$22,$D29) -> 0 | Y29: =SUMIFS(Y$3:Y$22,$C$3:$C$22,$C29,$D$3:$D$22,$D29) -> 0 | Z29: =SUMIFS(Z$3:Z$22,$C$3:$C$22,$C29,$D$3:$D$22,$D29) -> 0 | AA29: =SUMIFS(AA$3:AA$22,$C$3:$C$22,$C29,$D$3:$D$22,$D29) -> 0 | AB29: =SUMIFS(AB$3:AB$22,$C$3:$C$22,$C29,$D$3:$D$22,$D29) -> 0 | AC29: =SUMIFS(AC$3:AC$22,$C$3:$C$22,$C29,$D$3:$D$22,$D29) -> 0 | AD29: =SUMIFS(AD$3:AD$22,$C$3:$C$22,$C29,$D$3:$D$22,$D29) -> 0 | AE29: =SUMIFS(AE$3:AE$22,$C$3:$C$22,$C29,$D$3:$D$22,$D29) -> 0 | AF29: =IFERROR(X29/AB29,0) -> 0 | AG29: =IFERROR(Y29/AC29,0) -> 0 | AH29: =IFERROR(Z29/AD29,0) -> 0 | AI29: =IFERROR(AA29/AE29,0) -> 0 | AJ29: =IFERROR(AH29/AG29-1,"")
C30: Distribution | D30: Distribution | E30: =SUMIFS(E$3:E$22,$C$3:$C$22,$C30,$D$3:$D$22,$D30) -> 0 | F30: =SUMIFS(F$3:F$22,$C$3:$C$22,$C30,$D$3:$D$22,$D30) -> 0 | G30: =SUMIFS(G$3:G$22,$C$3:$C$22,$C30,$D$3:$D$22,$D30) -> 0 | H30: =SUMIFS(H$3:H$22,$C$3:$C$22,$C30,$D$3:$D$22,$D30) -> 0 | I30: =E30/SUM(E$3:E$22) -> 0 | J30: =F30/SUM(F$3:F$22) -> 0 | K30: =G30/SUM(G$3:G$22) -> 0 | L30: =H30/SUM(H$3:H$22) -> 0 | M30: =(G30-F30)/SUM($F$3:$F$22) -> 0 | N30: =(H30-G30)/SUM($G$3:$G$22) -> 0 | O30: =SUMIFS(O$3:O$22,$C$3:$C$22,$C30,$D$3:$D$22,$D30) -> 0 | P30: =SUMIFS(P$3:P$22,$C$3:$C$22,$C30,$D$3:$D$22,$D30) -> 0 | Q30: =SUMIFS(Q$3:Q$22,$C$3:$C$22,$C30,$D$3:$D$22,$D30) -> 0 | R30: =SUMIFS(R$3:R$22,$C$3:$C$22,$C30,$D$3:$D$22,$D30) -> 0 | X30: =SUMIFS(X$3:X$22,$C$3:$C$22,$C30,$D$3:$D$22,$D30) -> 0 | Y30: =SUMIFS(Y$3:Y$22,$C$3:$C$22,$C30,$D$3:$D$22,$D30) -> 0 | Z30: =SUMIFS(Z$3:Z$22,$C$3:$C$22,$C30,$D$3:$D$22,$D30) -> 0 | AA30: =SUMIFS(AA$3:AA$22,$C$3:$C$22,$C30,$D$3:$D$22,$D30) -> 0 | AB30: =SUMIFS(AB$3:AB$22,$C$3:$C$22,$C30,$D$3:$D$22,$D30) -> 0 | AC30: =SUMIFS(AC$3:AC$22,$C$3:$C$22,$C30,$D$3:$D$22,$D30) -> 0 | AD30: =SUMIFS(AD$3:AD$22,$C$3:$C$22,$C30,$D$3:$D$22,$D30) -> 0 | AE30: =SUMIFS(AE$3:AE$22,$C$3:$C$22,$C30,$D$3:$D$22,$D30) -> 0 | AF30: =IFERROR(X30/AB30,0) -> 0 | AG30: =IFERROR(Y30/AC30,0) -> 0 | AH30: =IFERROR(Z30/AD30,0) -> 0 | AI30: =IFERROR(AA30/AE30,0) -> 0 | AJ30: =IFERROR(AH30/AG30-1,"")
C31: Discount | D31: Discount | E31: =SUMIFS(E$3:E$22,$C$3:$C$22,$C31,$D$3:$D$22,$D31) -> 8683.6671 | F31: =SUMIFS(F$3:F$22,$C$3:$C$22,$C31,$D$3:$D$22,$D31) -> 3531.7831 | G31: =SUMIFS(G$3:G$22,$C$3:$C$22,$C31,$D$3:$D$22,$D31) -> 4071.3611 | H31: =SUMIFS(H$3:H$22,$C$3:$C$22,$C31,$D$3:$D$22,$D31) -> 1080.5228 | I31: =E31/SUM(E$3:E$22) -> 0.087941858 | J31: =F31/SUM(F$3:F$22) -> 0.10521195 | K31: =G31/SUM(G$3:G$22) -> 0.12863698 | L31: =H31/SUM(H$3:H$22) -> 0.032230362 | M31: =(G31-F31)/SUM($F$3:$F$22) -> 0.016074048 | N31: =(H31-G31)/SUM($G$3:$G$22) -> -0.094497244 | O31: =SUMIFS(O$3:O$22,$C$3:$C$22,$C31,$D$3:$D$22,$D31) -> 7.6799676e+08 | P31: =SUMIFS(P$3:P$22,$C$3:$C$22,$C31,$D$3:$D$22,$D31) -> 2.9993542e+08 | Q31: =SUMIFS(Q$3:Q$22,$C$3:$C$22,$C31,$D$3:$D$22,$D31) -> 3.6808757e+08 | R31: =SUMIFS(R$3:R$22,$C$3:$C$22,$C31,$D$3:$D$22,$D31) -> 99973766 | X31: =SUMIFS(X$3:X$22,$C$3:$C$22,$C31,$D$3:$D$22,$D31) -> 0 | Y31: =SUMIFS(Y$3:Y$22,$C$3:$C$22,$C31,$D$3:$D$22,$D31) -> 0 | Z31: =SUMIFS(Z$3:Z$22,$C$3:$C$22,$C31,$D$3:$D$22,$D31) -> 0 | AA31: =SUMIFS(AA$3:AA$22,$C$3:$C$22,$C31,$D$3:$D$22,$D31) -> 0 | AB31: =SUMIFS(AB$3:AB$22,$C$3:$C$22,$C31,$D$3:$D$22,$D31) -> 0 | AC31: =SUMIFS(AC$3:AC$22,$C$3:$C$22,$C31,$D$3:$D$22,$D31) -> 0 | AD31: =SUMIFS(AD$3:AD$22,$C$3:$C$22,$C31,$D$3:$D$22,$D31) -> 0 | AE31: =SUMIFS(AE$3:AE$22,$C$3:$C$22,$C31,$D$3:$D$22,$D31) -> 0 | AF31: =IFERROR(X31/AB31,0) -> 0 | AG31: =IFERROR(Y31/AC31,0) -> 0 | AH31: =IFERROR(Z31/AD31,0) -> 0 | AI31: =IFERROR(AA31/AE31,0) -> 0 | AJ31: =IFERROR(AH31/AG31-1,"")
C32: Media | D32: Digital | E32: =SUMIFS(E$3:E$22,$C$3:$C$22,$C32,$D$3:$D$22,$D32) -> 5498.9511 | F32: =SUMIFS(F$3:F$22,$C$3:$C$22,$C32,$D$3:$D$22,$D32) -> 1.1826741e-06 | G32: =SUMIFS(G$3:G$22,$C$3:$C$22,$C32,$D$3:$D$22,$D32) -> 2339.0949 | H32: =SUMIFS(H$3:H$22,$C$3:$C$22,$C32,$D$3:$D$22,$D32) -> 3159.8562 | I32: =E32/SUM(E$3:E$22) -> 0.055689373 | J32: =F32/SUM(F$3:F$22) -> 3.5231904e-11 | K32: =G32/SUM(G$3:G$22) -> 0.073905038 | L32: =H32/SUM(H$3:H$22) -> 0.094253732 | M32: =(G32-F32)/SUM($F$3:$F$22) -> 0.06968172 | N32: =(H32-G32)/SUM($G$3:$G$22) -> 0.025932423 | O32: =SUMIFS(O$3:O$22,$C$3:$C$22,$C32,$D$3:$D$22,$D32) -> 5.1585492e+08 | P32: =SUMIFS(P$3:P$22,$C$3:$C$22,$C32,$D$3:$D$22,$D32) -> 0.10426562 | Q32: =SUMIFS(Q$3:Q$22,$C$3:$C$22,$C32,$D$3:$D$22,$D32) -> 2.1371083e+08 | R32: =SUMIFS(R$3:R$22,$C$3:$C$22,$C32,$D$3:$D$22,$D32) -> 3.0214408e+08 | S32: =IFERROR(O32/X32,0) -> 2.3498108 | T32: =IFERROR(P32/Y32,0) -> 0 | U32: =IFERROR(Q32/Z32,0) -> 2.8319962 | V32: =IFERROR(R32/AA32,0) -> 2.0972406 | W32: =IFERROR(V32/U32-1,0) -> -0.25944794 | X32: =SUMIFS(X$3:X$22,$C$3:$C$22,$C32,$D$3:$D$22,$D32) -> 2.195304e+08 | Y32: =SUMIFS(Y$3:Y$22,$C$3:$C$22,$C32,$D$3:$D$22,$D32) -> 0 | Z32: =SUMIFS(Z$3:Z$22,$C$3:$C$22,$C32,$D$3:$D$22,$D32) -> 75462965 | AA32: =SUMIFS(AA$3:AA$22,$C$3:$C$22,$C32,$D$3:$D$22,$D32) -> 1.4406744e+08 | AB32: =SUMIFS(AB$3:AB$22,$C$3:$C$22,$C32,$D$3:$D$22,$D32) -> 273279319 | AC32: =SUMIFS(AC$3:AC$22,$C$3:$C$22,$C32,$D$3:$D$22,$D32) -> 0 | AD32: =SUMIFS(AD$3:AD$22,$C$3:$C$22,$C32,$D$3:$D$22,$D32) -> 81890403 | AE32: =SUMIFS(AE$3:AE$22,$C$3:$C$22,$C32,$D$3:$D$22,$D32) -> 191388916 | AF32: =IFERROR(X32/AB32,0) -> 0.80331876 | AG32: =IFERROR(Y32/AC32,0) -> 0 | AH32: =IFERROR(Z32/AD32,0) -> 0.92151171 | AI32: =IFERROR(AA32/AE32,0) -> 0.75274704 | AJ32: =IFERROR(AI32/AH32-1,0) -> -0.18313893
C33: Media | D33: OOH | E33: =SUMIFS(E$3:E$22,$C$3:$C$22,$C33,$D$3:$D$22,$D33) -> 2429.6933 | F33: =SUMIFS(F$3:F$22,$C$3:$C$22,$C33,$D$3:$D$22,$D33) -> 3.5579264e-07 | G33: =SUMIFS(G$3:G$22,$C$3:$C$22,$C33,$D$3:$D$22,$D33) -> 888.59393 | H33: =SUMIFS(H$3:H$22,$C$3:$C$22,$C33,$D$3:$D$22,$D33) -> 1541.0994 | I33: =E33/SUM(E$3:E$22) -> 0.024606165 | J33: =F33/SUM(F$3:F$22) -> 1.0599075e-11 | K33: =G33/SUM(G$3:G$22) -> 0.028075633 | L33: =H33/SUM(H$3:H$22) -> 0.045968664 | M33: =(G33-F33)/SUM($F$3:$F$22) -> 0.026471245 | N33: =(H33-G33)/SUM($G$3:$G$22) -> 0.020616282 | O33: =SUMIFS(O$3:O$22,$C$3:$C$22,$C33,$D$3:$D$22,$D33) -> 2.2726868e+08 | P33: =SUMIFS(P$3:P$22,$C$3:$C$22,$C33,$D$3:$D$22,$D33) -> 0.031526357 | Q33: =SUMIFS(Q$3:Q$22,$C$3:$C$22,$C33,$D$3:$D$22,$D33) -> 81191983 | R33: =SUMIFS(R$3:R$22,$C$3:$C$22,$C33,$D$3:$D$22,$D33) -> 1.460767e+08 | S33: =IFERROR(O33/X33,0) -> 2.3606218 | T33: =IFERROR(P33/Y33,0) -> 0 | U33: =IFERROR(Q33/Z33,0) -> 1.2666257 | V33: =IFERROR(R33/AA33,0) -> 4.5402218 | W33: =IFERROR(V33/U33-1,0) -> 2.5845016 | X33: =SUMIFS(X$3:X$22,$C$3:$C$22,$C33,$D$3:$D$22,$D33) -> 96274922 | Y33: =SUMIFS(Y$3:Y$22,$C$3:$C$22,$C33,$D$3:$D$22,$D33) -> 0 | Z33: =SUMIFS(Z$3:Z$22,$C$3:$C$22,$C33,$D$3:$D$22,$D33) -> 64101009 | AA33: =SUMIFS(AA$3:AA$22,$C$3:$C$22,$C33,$D$3:$D$22,$D33) -> 32173913 | AB33: =SUMIFS(AB$3:AB$22,$C$3:$C$22,$C33,$D$3:$D$22,$D33) -> 748.00316 | AC33: =SUMIFS(AC$3:AC$22,$C$3:$C$22,$C33,$D$3:$D$22,$D33) -> 0 | AD33: =SUMIFS(AD$3:AD$22,$C$3:$C$22,$C33,$D$3:$D$22,$D33) -> 647.15156 | AE33: =SUMIFS(AE$3:AE$22,$C$3:$C$22,$C33,$D$3:$D$22,$D33) -> 100.8516 | AF33: =IFERROR(X33/AB33,0) -> 128709.25 | AG33: =IFERROR(Y33/AC33,0) -> 0 | AH33: =IFERROR(Z33/AD33,0) -> 99051 | AI33: =IFERROR(AA33/AE33,0) -> 319022.33 | AJ33: =IFERROR(AI33/AH33-1,0) -> 2.2207886
C34: Comp Media | D34: Comp TV | E34: =SUMIFS(E$3:E$22,$C$3:$C$22,$C34,$D$3:$D$22,$D34) -> 0 | F34: =SUMIFS(F$3:F$22,$C$3:$C$22,$C34,$D$3:$D$22,$D34) -> 0 | G34: =SUMIFS(G$3:G$22,$C$3:$C$22,$C34,$D$3:$D$22,$D34) -> 0 | H34: =SUMIFS(H$3:H$22,$C$3:$C$22,$C34,$D$3:$D$22,$D34) -> 0 | I34: =E34/SUM(E$3:E$22) -> 0 | J34: =F34/SUM(F$3:F$22) -> 0 | K34: =G34/SUM(G$3:G$22) -> 0 | L34: =H34/SUM(H$3:H$22) -> 0 | M34: =(G34-F34)/SUM($F$3:$F$22) -> 0 | N34: =(H34-G34)/SUM($G$3:$G$22) -> 0 | O34: =SUMIFS(O$3:O$22,$C$3:$C$22,$C34,$D$3:$D$22,$D34) -> 0 | P34: =SUMIFS(P$3:P$22,$C$3:$C$22,$C34,$D$3:$D$22,$D34) -> 0 | Q34: =SUMIFS(Q$3:Q$22,$C$3:$C$22,$C34,$D$3:$D$22,$D34) -> 0 | R34: =SUMIFS(R$3:R$22,$C$3:$C$22,$C34,$D$3:$D$22,$D34) -> 0
C35: External | D35: External | E35: =SUMIFS(E$3:E$22,$C$3:$C$22,$C35,$D$3:$D$22,$D35) -> 0 | F35: =SUMIFS(F$3:F$22,$C$3:$C$22,$C35,$D$3:$D$22,$D35) -> 0 | G35: =SUMIFS(G$3:G$22,$C$3:$C$22,$C35,$D$3:$D$22,$D35) -> 0 | H35: =SUMIFS(H$3:H$22,$C$3:$C$22,$C35,$D$3:$D$22,$D35) -> 0 | I35: =E35/SUM(E$3:E$22) -> 0 | J35: =F35/SUM(F$3:F$22) -> 0 | K35: =G35/SUM(G$3:G$22) -> 0 | L35: =H35/SUM(H$3:H$22) -> 0 | M35: =(G35-F35)/SUM($F$3:$F$22) -> 0 | N35: =(H35-G35)/SUM($G$3:$G$22) -> 0 | O35: =SUMIFS(O$3:O$22,$C$3:$C$22,$C35,$D$3:$D$22,$D35) -> 0 | P35: =SUMIFS(P$3:P$22,$C$3:$C$22,$C35,$D$3:$D$22,$D35) -> 0 | Q35: =SUMIFS(Q$3:Q$22,$C$3:$C$22,$C35,$D$3:$D$22,$D35) -> 0 | R35: =SUMIFS(R$3:R$22,$C$3:$C$22,$C35,$D$3:$D$22,$D35) -> 0
E38: Volume Contribution (in KG) | I38: Contribution % | M38: Due-to | O38: Revenue (in CLP) | S38: ROI | X38: Spends | AB38: Activity (Impressions, Clicks, GRPs, Search Index) | AF38: CPRP (Cost per Impressions/Click/GRP)
C39: Type | E39: Total | F39: FY_2022 | G39: FY_2023 | H39: FY_2024 | I39: Total | J39: FY_2022 | K39: FY_2023 | L39: FY_2024 | M39: FY23 vs FY22 (12 Months) | N39: FY24 vs FY23 (12 Months) | O39: Total | P39: FY_2022 | Q39: FY_2023 | R39: FY_2024 | S39: Total | T39: FY_2022 | U39: FY_2023 | V39: FY_2024 | W39: Change | X39: Total | Y39: FY_2022 | Z39: FY_2023 | AA39: FY_2024 | AB39: Total | AC39: FY_2022 | AD39: FY_2023 | AE39: FY_2024 | AF39: Total | AG39: FY_2022 | AH39: FY_2023 | AI39: FY_2024 | AJ39: Change
C40: Base | E40: =SUMIFS(E$3:E$22,$C$3:$C$22,$C40) -> 88765.075 | F40: =SUMIFS(F$3:F$22,$C$3:$C$22,$C40) -> 29452.635 | G40: =SUMIFS(G$3:G$22,$C$3:$C$22,$C40) -> 29748.318 | H40: =SUMIFS(H$3:H$22,$C$3:$C$22,$C40) -> 29564.123 | I40: =E40/SUM(E$3:E$22) -> 0.89894806 | J40: =F40/SUM(F$3:F$22) -> 0.87739504 | K40: =G40/SUM(G$3:G$22) -> 0.9399151 | L40: =H40/SUM(H$3:H$22) -> 0.88185307 | M40: =(G40-F40)/SUM($F$3:$F$22) -> 0.0088084252 | N40: =(H40-G40)/SUM($G$3:$G$22) -> -0.0058197644 | O40: =SUMIFS(O$3:O$22,$C$3:$C$22,$C40) -> 8.170997e+09 | P40: =SUMIFS(P$3:P$22,$C$3:$C$22,$C40) -> 2.5991958e+09 | Q40: =SUMIFS(Q$3:Q$22,$C$3:$C$22,$C40) -> 2.7541831e+09 | R40: =SUMIFS(R$3:R$22,$C$3:$C$22,$C40) -> 2.8176181e+09
C41: Twinings' Price | E41: =SUMIFS(E$3:E$22,$C$3:$C$22,$C41) -> -11484.703 | F41: =SUMIFS(F$3:F$22,$C$3:$C$22,$C41) -> -2409.3376 | G41: =SUMIFS(G$3:G$22,$C$3:$C$22,$C41) -> -6205.798 | H41: =SUMIFS(H$3:H$22,$C$3:$C$22,$C41) -> -2869.5675 | I41: =E41/SUM(E$3:E$22) -> -0.11630871 | J41: =F41/SUM(F$3:F$22) -> -0.071774255 | K41: =G41/SUM(G$3:G$22) -> -0.19607573 | L41: =H41/SUM(H$3:H$22) -> -0.085594858 | M41: =(G41-F41)/SUM($F$3:$F$22) -> -0.11309669 | N41: =(H41-G41)/SUM($G$3:$G$22) -> 0.10541011 | O41: =SUMIFS(O$3:O$22,$C$3:$C$22,$C41) -> -1.053808e+09 | P41: =SUMIFS(P$3:P$22,$C$3:$C$22,$C41) -> -2.0679123e+08 | Q41: =SUMIFS(Q$3:Q$22,$C$3:$C$22,$C41) -> -5.7441182e+08 | R41: =SUMIFS(R$3:R$22,$C$3:$C$22,$C41) -> -2.7260493e+08
C42: Competitors' Price | E42: =SUMIFS(E$3:E$22,$C$3:$C$22,$C42) -> 8556.7858 | F42: =SUMIFS(F$3:F$22,$C$3:$C$22,$C42) -> 1026.7715 | G42: =SUMIFS(G$3:G$22,$C$3:$C$22,$C42) -> 3222.3833 | H42: =SUMIFS(H$3:H$22,$C$3:$C$22,$C42) -> 4307.631 | I42: =E42/SUM(E$3:E$22) -> 0.086656897 | J42: =F42/SUM(F$3:F$22) -> 0.03058756 | K42: =G42/SUM(G$3:G$22) -> 0.10181304 | L42: =H42/SUM(H$3:H$22) -> 0.12849012 | M42: =(G42-F42)/SUM($F$3:$F$22) -> 0.065407354 | N42: =(H42-G42)/SUM($G$3:$G$22) -> 0.034289022 | O42: =SUMIFS(O$3:O$22,$C$3:$C$22,$C42) -> 8.0216579e+08 | P42: =SUMIFS(P$3:P$22,$C$3:$C$22,$C42) -> 92837964 | Q42: =SUMIFS(Q$3:Q$22,$C$3:$C$22,$C42) -> 2.9830993e+08 | R42: =SUMIFS(R$3:R$22,$C$3:$C$22,$C42) -> 4.110179e+08
C43: Twinings' Distribution | E43: =SUMIFS(E$3:E$22,$C$3:$C$22,$C43) -> 9366.052 | F43: =SUMIFS(F$3:F$22,$C$3:$C$22,$C43) -> 3370.9159 | G43: =SUMIFS(G$3:G$22,$C$3:$C$22,$C43) -> 1964.0368 | H43: =SUMIFS(H$3:H$22,$C$3:$C$22,$C43) -> 4031.0994 | I43: =E43/SUM(E$3:E$22) -> 0.094852556 | J43: =F43/SUM(F$3:F$22) -> 0.1004197 | K43: =G43/SUM(G$3:G$22) -> 0.062054863 | L43: =H43/SUM(H$3:H$22) -> 0.1202416 | M43: =(G43-F43)/SUM($F$3:$F$22) -> -0.041910979 | N43: =(H43-G43)/SUM($G$3:$G$22) -> 0.065310023 | O43: =SUMIFS(O$3:O$22,$C$3:$C$22,$C43) -> 8.6580008e+08 | P43: =SUMIFS(P$3:P$22,$C$3:$C$22,$C43) -> 2.9909529e+08 | Q43: =SUMIFS(Q$3:Q$22,$C$3:$C$22,$C43) -> 1.8114113e+08 | R43: =SUMIFS(R$3:R$22,$C$3:$C$22,$C43) -> 3.8556365e+08
C44: Competitors' Distribution | E44: =SUMIFS(E$3:E$22,$C$3:$C$22,$C44) -> -4392.7024 | F44: =SUMIFS(F$3:F$22,$C$3:$C$22,$C44) -> -948.99476 | G44: =SUMIFS(G$3:G$22,$C$3:$C$22,$C44) -> -911.16153 | H44: =SUMIFS(H$3:H$22,$C$3:$C$22,$C44) -> -2532.5461 | I44: =E44/SUM(E$3:E$22) -> -0.044486091 | J44: =F44/SUM(F$3:F$22) -> -0.028270588 | K44: =G44/SUM(G$3:G$22) -> -0.028788669 | L44: =H44/SUM(H$3:H$22) -> -0.07554202 | M44: =(G44-F44)/SUM($F$3:$F$22) -> 0.0011270533 | N44: =(H44-G44)/SUM($G$3:$G$22) -> -0.05122857 | O44: =SUMIFS(O$3:O$22,$C$3:$C$22,$C44) -> -4.1014827e+08 | P44: =SUMIFS(P$3:P$22,$C$3:$C$22,$C44) -> -84294846 | Q44: =SUMIFS(Q$3:Q$22,$C$3:$C$22,$C44) -> -84417543 | R44: =SUMIFS(R$3:R$22,$C$3:$C$22,$C44) -> -2.4143588e+08
C45: Discount | E45: =SUMIFS(E$3:E$22,$C$3:$C$22,$C45) -> 8683.6671 | F45: =SUMIFS(F$3:F$22,$C$3:$C$22,$C45) -> 3531.7831 | G45: =SUMIFS(G$3:G$22,$C$3:$C$22,$C45) -> 4071.3611 | H45: =SUMIFS(H$3:H$22,$C$3:$C$22,$C45) -> 1080.5228 | I45: =E45/SUM(E$3:E$22) -> 0.087941858 | J45: =F45/SUM(F$3:F$22) -> 0.10521195 | K45: =G45/SUM(G$3:G$22) -> 0.12863698 | L45: =H45/SUM(H$3:H$22) -> 0.032230362 | M45: =(G45-F45)/SUM($F$3:$F$22) -> 0.016074048 | N45: =(H45-G45)/SUM($G$3:$G$22) -> -0.094497244 | O45: =SUMIFS(O$3:O$22,$C$3:$C$22,$C45) -> 7.6799676e+08 | P45: =SUMIFS(P$3:P$22,$C$3:$C$22,$C45) -> 2.9993542e+08 | Q45: =SUMIFS(Q$3:Q$22,$C$3:$C$22,$C45) -> 3.6808757e+08 | R45: =SUMIFS(R$3:R$22,$C$3:$C$22,$C45) -> 99973766
...

Sheet Decomposition
A1: Year | D1: Period | E1: APE | F1: Residual | G1: Base | H1: Twinings_Price | I1: Competitor_Price | J1: Twinings_WD | K1: Competitor_WD | L1: Discounts_5%_Min | M1: YouTube_FB_Impressions | N1: Google_Search_Clicks | O1: Display_Impressions | P1: OOH_Screen_GRPs | Q1: OOH_Retail_GRPs | R1: Competitor_GRPs | S1: Inflation | T1: Temperature | U1: Covid_Index | V1: Winter_Solstice | W1: Independence_Month | BB1: Revenue Contribution | BD1: Twinings_Price | BF1: =G1 -> Base | BG1: =H1 -> Twinings_Price | BH1: =I1 -> Competitor_Price | BI1: =J1 -> Twinings_WD | BJ1: =K1 -> Competitor_WD | BK1: =L1 -> Discounts_5%_Min | BL1: =M1 -> YouTube_FB_Impressions | BM1: =N1 -> Google_Search_Clicks | ... BV1: =W1 -> Independence_Month
A2: FY_2022 | D2: 44440 | E2: =AVP!G2 -> 0.020832139 | F2: =AVP!F2 -> -68.953714 | G2: 2486.3069 | H2: -405.80771 | I2: 23.457837 | J2: 88.337517 | K2: -41.214992 | L2: 602.36364 | M2: 4.531819e-08 | N2: 2.4060811e-08 | O2: 3.5499081e-08 | P2: 2.0910124e-08 | Q2: 3.6233767e-09 | R2: -72.034822 | S2: -138.30448 | T2: -190.76284 | U2: 508.04528 | V2: 0 | W2: 518.53543 | BD2: 81075.729 | BF2: =$BD2*G2 -> 2.0157914e+08 | BG2: =$BD2*H2 -> -32901156 | BH2: =$BD2*I2 -> 1901861.3 | BI2: =$BD2*J2 -> 7162028.6 | BJ2: =$BD2*K2 -> -3341535.5 | BK2: =$BD2*L2 -> 48837071 | BL2: =$BD2*M2 -> 0.0036742053 | BM2: =$BD2*N2 -> 0.0019507478 | ... BV2: =$BD2*W2 -> 42040638
A3: FY_2022 | D3: 44470 | E3: =AVP!G3 -> 0.030978031 | F3: =AVP!F3 -> 93.810709 | G3: 2472.805 | H3: -300.40606 | I3: 3.2519825 | J3: 348.14223 | K3: -77.633851 | L3: 662.25311 | M3: 4.4237049e-08 | N3: 2.3685674e-08 | O3: 3.5473091e-08 | P3: 2.2251739e-08 | Q3: 3.9543283e-09 | R3: -72.448133 | S3: -156.9812 | T3: -312.01809 | U3: 367.52229 | V3: 0 | W3: 0 | BD3: 82223.331 | BF3: =$BD3*G3 -> 2.0332227e+08 | BG3: =$BD3*H3 -> -24700387 | BH3: =$BD3*I3 -> 267388.84 | BI3: =$BD3*J3 -> 28625414 | BJ3: =$BD3*K3 -> -6383313.8 | BK3: =$BD3*L3 -> 54452657 | BL3: =$BD3*M3 -> 0.0036373175 | BM3: =$BD3*N3 -> 0.001947515 | ... BV3: =$BD3*W3 -> 0
A4: FY_2022 | D4: 44501 | E4: =AVP!G4 -> 0.070298552 | F4: =AVP!F4 -> -177.54328 | G4: 2469.04 | H4: -296.87094 | I4: 0 | J4: 317.97258 | K4: -106.07662 | L4: 581.10768 | M4: 4.3414245e-08 | N4: 2.3657323e-08 | O4: 3.5278081e-08 | P4: 2.3129084e-08 | Q4: 3.9226535e-09 | R4: -79.62436 | S4: -58.628364 | T4: -450.0894 | U4: 326.27371 | V4: 0 | W4: 0 | BD4: 84167.764 | BF4: =$BD4*G4 -> 2.0781358e+08 | BG4: =$BD4*H4 -> -24986963 | BH4: =$BD4*I4 -> 0 | BI4: =$BD4*J4 -> 26763041 | BJ4: =$BD4*K4 -> -8928232.2 | BK4: =$BD4*L4 -> 48910534 | BL4: =$BD4*M4 -> 0.00365408 | BM4: =$BD4*N4 -> 0.001991184 | ... BV4: =$BD4*W4 -> 0
A5: FY_2022 | D5: 44531 | E5: =AVP!G5 -> 0.16290526 | F5: =AVP!F5 -> 446.59825 | G5: 2447.4368 | H5: -142.06705 | I5: 16.15853 | J5: 312.59825 | K5: -82.661178 | L5: 91.953482 | M5: 4.2091654e-08 | N5: 2.3005334e-08 | O5: 3.5404535e-08 | P5: 2.4873794e-08 | Q5: 4.5340986e-09 | R5: -86.216046 | S5: -91.119559 | T5: -540.29592 | U5: 369.07441 | V5: 0 | W5: 0 | BD5: 95099.893 | BF5: =$BD5*G5 -> 2.3275098e+08 | BG5: =$BD5*H5 -> -13510561 | BH5: =$BD5*I5 -> 1536674.5 | BI5: =$BD5*J5 -> 29728060 | BJ5: =$BD5*K5 -> -7861069.2 | BK5: =$BD5*L5 -> 8744766.3 | BL5: =$BD5*M5 -> 0.0040029118 | BM5: =$BD5*N5 -> 0.0021878048 | ... BV5: =$BD5*W5 -> 0
A6: FY_2022 | D6: 44562 | E6: =AVP!G6 -> 0.090961251 | F6: =AVP!F6 -> -192.9098 | G6: 2469.8363 | H6: -328.68596 | I6: 11.907814 | J6: 250.44131 | K6: -67.563189 | L6: 474.28451 | M6: 4.216859e-08 | N6: 2.3638541e-08 | O6: 3.4775597e-08 | P6: 2.4087149e-08 | Q6: 3.8383432e-09 | R6: -43.124682 | S6: -142.97646 | T6: -620.55192 | U6: 310.13311 | V6: 0 | W6: 0 | BD6: 84380.01 | BF6: =$BD6*G6 -> 2.0840481e+08 | BG6: =$BD6*H6 -> -27734524 | BH6: =$BD6*I6 -> 1004781.4 | BI6: =$BD6*J6 -> 21132240 | BJ6: =$BD6*K6 -> -5700982.6 | BK6: =$BD6*L6 -> 40020131 | BL6: =$BD6*M6 -> 0.0035581861 | BM6: =$BD6*N6 -> 0.0019946204 | ... BV6: =$BD6*W6 -> 0
A7: FY_2022 | D7: 44593 | E7: =AVP!G7 -> 0.19669296 | F7: =AVP!F7 -> -398.39648 | G7: 2473.4603 | H7: -401.39174 | I7: 32.352805 | J7: 312.15807 | K7: -73.834497 | L7: 407.44942 | M7: 4.1765391e-08 | N7: 2.3647195e-08 | O7: 3.4416747e-08 | P7: 2.4321727e-08 | Q7: 3.7176595e-09 | R7: -2.0469915 | S7: -34.694541 | T7: -591.38525 | U7: 301.80291 | V7: 0 | W7: 0 | BD7: 87097.274 | BF7: =$BD7*G7 -> 2.1543165e+08 | BG7: =$BD7*H7 -> -34960127 | BH7: =$BD7*I7 -> 2817841.2 | BI7: =$BD7*J7 -> 27188117 | BJ7: =$BD7*K7 -> -6430783.4 | BK7: =$BD7*L7 -> 35487734 | BL7: =$BD7*M7 -> 0.0036376517 | BM7: =$BD7*N7 -> 0.0020596062 | ... BV7: =$BD7*W7 -> 0
A8: FY_2022 | D8: 44621 | E8: =AVP!G8 -> 0.13090128 | F8: =AVP!F8 -> 364.27812 | G8: 2439.2559 | H8: -78.363982 | I8: 95.651762 | J8: 302.2904 | K8: -68.995241 | L8: 67.796035 | M8: 4.0555644e-08 | N8: 2.2296515e-08 | O8: 3.4657263e-08 | P8: 2.6368881e-08 | Q8: 4.9411717e-09 | R8: -0.0099414147 | S8: -217.05787 | T8: -486.65614 | U8: 364.65694 | V8: 0 | W8: 0 | BD8: 90924.408 | BF8: =$BD8*G8 -> 2.217879e+08 | BG8: =$BD8*H8 -> -7125198.7 | BH8: =$BD8*I8 -> 8697079.8 | BI8: =$BD8*J8 -> 27485576 | BJ8: =$BD8*K8 -> -6273351.5 | BK8: =$BD8*L8 -> 6164314.4 | BL8: =$BD8*M8 -> 0.0036874979 | BM8: =$BD8*N8 -> 0.0020272974 | ... BV8: =$BD8*W8 -> 0
A9: FY_2022 | D9: 44652 | E9: =AVP!G9 -> 0.015193871 | F9: =AVP!F9 -> -37.791168 | G9: 2438.6478 | H9: -75.960646 | I9: 117.77452 | J9: 192.71114 | K9: -28.260112 | L9: 10.168074 | M9: 4.0245759e-08 | N9: 2.1978655e-08 | O9: 3.4332068e-08 | P9: 2.6549414e-08 | Q9: 5.1215194e-09 | R9: -4.7360961e-05 | S9: -164.29248 | T9: -309.48337 | U9: 343.75031 | V9: 0 | W9: 0 | BD9: 90669.818 | BF9: =$BD9*G9 -> 2.2111175e+08 | BG9: =$BD9*H9 -> -6887337.9 | BH9: =$BD9*I9 -> 10678594 | BI9: =$BD9*J9 -> 17473084 | BJ9: =$BD9*K9 -> -2562339.2 | BK9: =$BD9*L9 -> 921937.44 | BL9: =$BD9*M9 -> 0.0036490757 | BM9: =$BD9*N9 -> 0.0019928006 | ... BV9: =$BD9*W9 -> 0
A10: FY_2022 | D10: 44682 | E10: =AVP!G10 -> 0.0041514197 | F10: =AVP!F10 -> 13.397744 | G10: 2434.8381 | H10: -36.49203 | I10: 171.79209 | J10: 376.43802 | K10: -54.308505 | L10: 256.57738 | M10: 3.9836385e-08 | N10: 2.1548683e-08 | O10: 3.4051022e-08 | P10: 2.6916924e-08 | Q10: 5.4112787e-09 | R10: -1.1326818e-06 | S10: -141.06156 | T10: -149.1075 | U10: 355.19429 | V10: 0 | W10: 0 | BD10: 89706.497 | BF10: =$BD10*G10 -> 2.1842079e+08 | BG10: =$BD10*H10 -> -3273572.2 | BH10: =$BD10*I10 -> 15410866 | BI10: =$BD10*J10 -> 33768936 | BJ10: =$BD10*K10 -> -4871825.8 | BK10: =$BD10*L10 -> 23016658 | BL10: =$BD10*M10 -> 0.0035735826 | BM10: =$BD10*N10 -> 0.0019330568 | ... BV10: =$BD10*W10 -> 0
A11: FY_2022 | D11: 44713 | E11: =AVP!G11 -> 0.024908859 | F11: =AVP!F11 -> 92.6688 | G11: 2432.474 | H11: -30.561234 | I11: 167.88313 | J11: 324.65844 | K11: -127.21848 | L11: 38.675634 | M11: 3.9499785e-08 | N11: 2.1176057e-08 | O11: 3.3759914e-08 | P11: 2.7183723e-08 | Q11: 5.6534115e-09 | R11: -0.018397855 | S11: -109.99467 | T11: -25.598204 | U11: 361.5561 | V11: 595.78993 | W11: 0 | BD11: 93718.949 | BF11: =$BD11*G11 -> 2.279689e+08 | BG11: =$BD11*H11 -> -2864166.8 | BH11: =$BD11*I11 -> 15733830 | BI11: =$BD11*J11 -> 30426648 | BJ11: =$BD11*K11 -> -11922783 | BK11: =$BD11*L11 -> 3624639.8 | BL11: =$BD11*M11 -> 0.0037018783 | BM11: =$BD11*N11 -> 0.0019845978 | ... BV11: =$BD11*W11 -> 0
A12: FY_2022 | D12: 44743 | E12: =AVP!G12 -> 0.042860436 | F12: =AVP!F12 -> 126.15708 | G12: 2437.3293 | H12: -87.756429 | I12: 182.68614 | J12: 313.23141 | K12: -126.241 | L12: 5.7017983 | M12: 3.9339584e-08 | N12: 2.1027383e-08 | O12: 3.3380169e-08 | P12: 2.706525e-08 | Q12: 5.6287082e-09 | R12: -100.3737 | S12: -163.51 | T12: 0 | U12: 356.21444 | V12: 0 | W12: 0 | BD12: 92625.097 | BF12: =$BD12*G12 -> 2.2575786e+08 | BG12: =$BD12*H12 -> -8128447.8 | BH12: =$BD12*I12 -> 16921321 | BI12: =$BD12*J12 -> 29013089 | BJ12: =$BD12*K12 -> -11693085 | BK12: =$BD12*L12 -> 528129.62 | BL12: =$BD12*M12 -> 0.0036438328 | BM12: =$BD12*N12 -> 0.0019476633 | ... BV12: =$BD12*W12 -> 0
A13: FY_2022 | D13: 44774 | E13: =AVP!G13 -> 0.02101976 | F13: =AVP!F13 -> -60.050363 | G13: 2451.2042 | H13: -224.97387 | I13: 203.8549 | J13: 231.93651 | K13: -94.987085 | L13: 333.45236 | M13: 3.9434355e-08 | N13: 2.1271468e-08 | O13: 3.2746273e-08 | P13: 2.6559694e-08 | Q13: 5.2285826e-09 | R13: -96.92285 | S13: -146.27735 | T13: -73.15946 | U13: 332.77597 | V13: 0 | W13: 0 | BD13: 87649.231 | BF13: =$BD13*G13 -> 2.1484617e+08 | BG13: =$BD13*H13 -> -19718786 | BH13: =$BD13*I13 -> 17867725 | BI13: =$BD13*J13 -> 20329057 | BJ13: =$BD13*K13 -> -8325545 | BK13: =$BD13*L13 -> 29226843 | BL13: =$BD13*M13 -> 0.0034563908 | BM13: =$BD13*N13 -> 0.0018644278 | ... BV13: =$BD13*W13 -> 0
... A22: FY_2023 | D22: 45047 | E22: =AVP!G22 -> 0.10315112 | F22: =AVP!F22 -> 281.60163 | G22: 2477.2815 | H22: -452.53099 | I22: 305.55373 | J22: 68.717994 | K22: -50.622441 | L22: 319.94457 | M22: 3.9197159e-08 | N22: 1.7443191e-08 | O22: 2.901106e-08 | P22: 2.2857843e-08 | Q22: 8.1988582e-09 | R22: -0.0047167484 | S22: -40.386887 | T22: -179.5634 | U22: 0 | V22: 0 | W22: 0 | BD22: 92943.709 | BF22: =$BD22*G22 -> 2.3024773e+08 | BG22: =$BD22*H22 -> -42059909 | BH22: =$BD22*I22 -> 28399297 | BI22: =$BD22*J22 -> 6386905.2 | BJ22: =$BD22*K22 -> -4705037.4 | BK22: =$BD22*L22 -> 29736835 | BL22: =$BD22*M22 -> 0.0036431294 | BM22: =$BD22*N22 -> 0.0016212348 | ... BV22: =$BD22*W22 -> 0
A23: FY_2023 | B23: 2023 Campaign | C23: 2023 | D23: 45078 | E23: =AVP!G23 -> 0.035653821 | F23: =AVP!F23 -> -137.10745 | G23: 2498.5346 | H23: -679.46175 | I23: 284.52755 | J23: 93.771502 | K23: -99.0875 | L23: 410.60916 | M23: 388.39792 | N23: 30.654477 | O23: 261.2774 | P23: 224.1308 | Q23: 73.835672 | R23: -91.053202 | S23: 55.313237 | T23: -53.998652 | U23: 0 | V23: 585.17521 | W23: 0 | BD23: 90919.335 | BF23: =$BD23*G23 -> 2.2716511e+08 | BG23: =$BD23*H23 -> -61776211 | BH23: =$BD23*I23 -> 25869055 | BI23: =$BD23*J23 -> 8525642.6 | BJ23: =$BD23*K23 -> -9008969.6 | BK23: =$BD23*L23 -> 37332312 | BL23: =$BD23*M23 -> 35312881 | BM23: =$BD23*N23 -> 2787084.7 | ... BV23: =$BD23*W23 -> 0
A24: FY_2023 | B24: 2023 Campaign | C24: 2023 | D24: 45108 | E24: =AVP!G24 -> 0.093820138 | F24: =AVP!F24 -> -294.8933 | G24: 2512.4215 | H24: -813.04055 | I24: 295.73714 | J24: 99.307273 | K24: -122.37396 | L24: 463.00458 | M24: 396.7406 | N24: 174.83294 | O24: 271.09594 | P24: 218.48179 | Q24: 74.603108 | R24: -89.735572 | S24: -15.500809 | T24: -27.503681 | U24: 0 | V24: 0 | W24: 0 | BD24: 89381.705 | BF24: =$BD24*G24 -> 2.2456452e+08 | BG24: =$BD24*H24 -> -72670951 | BH24: =$BD24*I24 -> 26433490 | BI24: =$BD24*J24 -> 8876253.4 | BJ24: =$BD24*K24 -> -10937994 | BK24: =$BD24*L24 -> 41384139 | BL24: =$BD24*M24 -> 35461351 | BM24: =$BD24*N24 -> 15626867 | ... BV24: =$BD24*W24 -> 0
A25: FY_2023 | B25: 2023 Campaign | C25: 2023 | D25: 45139 | E25: =AVP!G25 -> 0.070709761 | F25: =AVP!F25 -> -195.64161 | G25: 2510.2357 | H25: -827.935 | I25: 293.57268 | J25: 0 | K25: -239.63471 | L25: 319.59723 | M25: 394.7645 | N25: 152.22997 | O25: 269.10112 | P25: 215.84954 | Q25: 81.693021 | R25: -90.556003 | S25: -15.259075 | T25: -101.19136 | U25: 0 | V25: 0 | W25: 0 | BD25: 93783.699 | BF25: =$BD25*G25 -> 2.3541919e+08 | BG25: =$BD25*H25 -> -77646807 | BH25: =$BD25*I25 -> 27532332 | BI25: =$BD25*J25 -> 0 | BJ25: =$BD25*K25 -> -22473830 | BK25: =$BD25*L25 -> 29973010 | BL25: =$BD25*M25 -> 37022475 | BM25: =$BD25*N25 -> 14276690 | ... BV25: =$BD25*W25 -> 0
A26: FY_2024 | B26: 2023 Campaign | C26: 2023 | D26: 45170 | E26: =AVP!G26 -> 0.0095316656 | F26: =AVP!F26 -> -32.209404 | G26: 2497.7848 | H26: -657.94596 | I26: 331.1934 | J26: 71.937966 | K26: -165.74097 | L26: 264.16657 | M26: 388.26951 | N26: 25.14559 | O26: 221.07722 | P26: 213.14819 | Q26: 93.950802 | R26: -93.834404 | S26: -81.357619 | T26: -216.32015 | U26: 0 | V26: 0 | W26: 519.93445 | BD26: 93036.894 | BF26: =$BD26*G26 -> 2.3238614e+08 | BG26: =$BD26*H26 -> -61213248 | BH26: =$BD26*I26 -> 30813205 | BI26: =$BD26*J26 -> 6692884.9 | BJ26: =$BD26*K26 -> -15420025 | BK26: =$BD26*L26 -> 24577237 | BL26: =$BD26*M26 -> 36123389 | BM26: =$BD26*N26 -> 2339467.6 | ... BV26: =$BD26*W26 -> 48373086
A27: FY_2024 | B27: 2023 Campaign | C27: 2023 | D27: 45200 | E27: =AVP!G27 -> 0.00088521304 | F27: =AVP!F27 -> -2.2200222 | G27: 2483.6866 | H27: -483.23578 | I27: 288.00572 | J27: 229.78127 | K27: -248.43222 | L27: 42.010684 | M27: 348.10024 | N27: 0.21286901 | O27: 31.454488 | P27: 191.53098 | Q27: 107.09681 | R27: -98.676793 | S27: -37.033358 | T27: -344.38549 | U27: 0 | V27: 0 | W27: 0 | BD27: 93810.545 | BF27: =$BD27*G27 -> 2.3299599e+08 | BG27: =$BD27*H27 -> -45332612 | BH27: =$BD27*I27 -> 27017973 | BI27: =$BD27*J27 -> 21555906 | BJ27: =$BD27*K27 -> -23305562 | BK27: =$BD27*L27 -> 3941045.1 | BL27: =$BD27*M27 -> 32655473 | BM27: =$BD27*N27 -> 19969.358 | ... BV27: =$BD27*W27 -> 0
A28: FY_2024 | C28: 2023 | D28: 45231 | E28: =AVP!G28 -> 0.018570585 | F28: =AVP!F28 -> 41.297601 | G28: 2469.4882 | H28: -317.09604 | I28: 303.69198 | J28: 201.45044 | K28: -233.32727 | L28: 6.6611923 | M28: 192.64356 | N28: 0.00066468974 | O28: 0.23669973 | P28: 121.22939 | Q28: 118.42979 | R28: -102.51484 | S28: -93.037843 | T28: -485.33554 | U28: 0 | V28: 0 | W28: 0 | BD28: 96699.351 | BF28: =$BD28*G28 -> 2.3879791e+08 | BG28: =$BD28*H28 -> -30662982 | BH28: =$BD28*I28 -> 29366818 | BI28: =$BD28*J28 -> 19480127 | BJ28: =$BD28*K28 -> -22562596 | BK28: =$BD28*L28 -> 644132.98 | BL28: =$BD28*M28 -> 18628507 | BM28: =$BD28*N28 -> 64.275066 | ... BV28: =$BD28*W28 -> 0
A29: FY_2024 | C29: 2023 | D29: 45261 | E29: =AVP!G29 -> 0.14122528 | F29: =AVP!F29 -> 414.69928 | G29: 2457.5901 | H29: -143.34458 | I29: 358.70944 | J29: 206.3175 | K29: -232.89211 | L29: 306.15348 | M29: 36.542491 | N29: 7.0487086e-06 | O29: 0.00080167269 | P29: 37.81912 | Q29: 111.21874 | R29: -93.874296 | S29: 65.043704 | T29: -587.54571 | U29: 0 | V29: 0 | W29: 0 | BD29: 91848.106 | BF29: =$BD29*G29 -> 2.25725e+08 | BG29: =$BD29*H29 -> -13165928 | BH29: =$BD29*I29 -> 32946782 | BI29: =$BD29*J29 -> 18949872 | BJ29: =$BD29*K29 -> -21390699 | BK29: =$BD29*L29 -> 28119618 | BL29: =$BD29*M29 -> 3356358.6 | BM29: =$BD29*N29 -> 0.64741054 | ... BV29: =$BD29*W29 -> 0
A30: FY_2024 | C30: 2023 | D30: 45292 | E30: =AVP!G30 -> 0.11969613 | F30: =AVP!F30 -> -197.52745 | G30: 2466.5158 | H30: -262.80847 | I30: 366.80436 | J30: 173.30839 | K30: -182.00252 | L30: 44.718573 | M30: 2.0851824 | N30: 4.2544307e-07 | O30: 9.8430011e-06 | P30: 4.8345857 | Q30: 64.572101 | R30: -86.148307 | S30: -83.308111 | T30: -660.80319 | U30: 0 | V30: 0 | W30: 0 | BD30: 95254.808 | BF30: =$BD30*G30 -> 2.3494749e+08 | BG30: =$BD30*H30 -> -25033770 | BH30: =$BD30*I30 -> 34939879 | BI30: =$BD30*J30 -> 16508458 | BJ30: =$BD30*K30 -> -17336615 | BK30: =$BD30*L30 -> 4259659 | BL30: =$BD30*M30 -> 198623.65 | BM30: =$BD30*N30 -> 0.040525498 | ... BV30: =$BD30*W30 -> 0
A31: FY_2024 | C31: 2023 | D31: 45323 | E31: =AVP!G31 -> 0.15898315 | F31: =AVP!F31 -> -239.73197 | G31: 2465.5534 | H31: -265.43209 | I31: 300.38691 | J31: 178.0944 | K31: -176.09808 | L31: 6.7279409 | M31: 0.059535282 | N31: 8.6703063e-08 | O31: 6.3899061e-07 | P31: 0.31827315 | Q31: 18.434886 | R31: -80.361086 | S31: -73.196175 | T31: -626.84791 | U31: 0 | V31: 0 | W31: 0 | BD31: 97401.97 | BF31: =$BD31*G31 -> 2.4014976e+08 | BG31: =$BD31*H31 -> -25853609 | BH31: =$BD31*I31 -> 29258277 | BI31: =$BD31*J31 -> 17346745 | BJ31: =$BD31*K31 -> -17152300 | BK31: =$BD31*L31 -> 655314.7 | BL31: =$BD31*M31 -> 5798.8538 | BM31: =$BD31*N31 -> 0.0084450491 | ... BV31: =$BD31*W31 -> 0
A32: FY_2024 | C32: 2023 | D32: 45352 | E32: =AVP!G32 -> 0.1205951 | F32: =AVP!F32 -> 343.81181 | G32: 2452.5354 | H32: -88.889636 | I32: 335.72503 | J32: 330.4026 | K32: -203.49607 | L32: 349.29427 | M32: 0.0017366023 | N32: 3.6148983e-08 | O32: 1.3983778e-07 | P32: 0.016276671 | Q32: 2.2716044 | R32: -90.405011 | S32: -46.660467 | T32: -533.64757 | U32: 0 | V32: 0 | W32: 0 | BD32: 91043.974 | BF32: =$BD32*G32 -> 2.2328857e+08 | BG32: =$BD32*H32 -> -8092865.7 | BH32: =$BD32*I32 -> 30565741 | BI32: =$BD32*J32 -> 30081166 | BJ32: =$BD32*K32 -> -18527091 | BK32: =$BD32*L32 -> 31801138 | BL32: =$BD32*M32 -> 158.10718 | BM32: =$BD32*N32 -> 0.0032911471 | ... BV32: =$BD32*W32 -> 0
A33: FY_2024 | B33: 2024 Campaign | C33: 2024 | D33: 45383 | E33: =AVP!G33 -> 0.054921557 | F33: =AVP!F33 -> -133.5237 | G33: 2457.0878 | H33: -175.31489 | I33: 403.41198 | J33: 337.21028 | K33: -217.04544 | L33: 51.634841 | M33: 212.743 | N33: 2.3880435e-08 | O33: 6.2159987e-08 | P33: 0.00090118799 | Q33: 0.1415737 | R33: -92.347599 | S33: -65.287895 | T33: -347.53987 | U33: 0 | V33: 0 | W33: 0 | BD33: 98408.435 | BF33: =$BD33*G33 -> 2.4179817e+08 | BG33: =$BD33*H33 -> -17252464 | BH33: =$BD33*I33 -> 39699141 | BI33: =$BD33*J33 -> 33184335 | BJ33: =$BD33*K33 -> -21359102 | BK33: =$BD33*L33 -> 5081303.9 | BL33: =$BD33*M33 -> 20935706 | BM33: =$BD33*N33 -> 0.0023500363 | ... BV33: =$BD33*W33 -> 0
A34: FY_2024 | B34: 2024 Campaign | C34: 2024 | D34: 45413 | E34: =AVP!G34 -> 0.0080035982 | F34: =AVP!F34 -> 24.560618 | G34: 2455.1185 | H34: -147.25453 | I34: 423.44366 | J34: 313.68342 | K34: -217.80848 | L34: 7.7925402 | M34: 375.13119 | N34: 73.117875 | O34: 4.1061125e-08 | P34: 7.2052681e-05 | Q34: 77.838029 | R34: -106.26174 | S34: -32.568116 | T34: -178.09604 | U34: 0 | V34: 0 | W34: 0 | BD34: 97880.884 | BF34: =$BD34*G34 -> 2.4030917e+08 | BG34: =$BD34*H34 -> -14413404 | BH34: =$BD34*I34 -> 41447040 | BI34: =$BD34*J34 -> 30703611 | BJ34: =$BD34*K34 -> -21319287 | BK34: =$BD34*L34 -> 762740.72 | BL34: =$BD34*M34 -> 36718173 | BM34: =$BD34*N34 -> 7156842.3 | ... BV34: =$BD34*W34 -> 0
A35: FY_2024 | B35: 2024 Campaign | C35: 2024 | D35: 45444 | E35: =AVP!G35 -> 0.0099044476 | F35: =AVP!F35 -> 40.218594 | G35: 2454.2686 | H35: -130.51414 | I35: 386.58614 | J35: 533.49589 | K35: -243.65024 | L35: 1.1687171 | M35: 375.12123 | N35: 77.45752 | O35: 3.326942e-08 | P35: 9.097344e-06 | Q35: 122.29204 | R35: -108.22723 | S35: 11.04837 | T35: -47.776533 | U35: 0 | V35: 589.17107 | W35: 0 | BD35: 96640.306 | BF35: =$BD35*G35 -> 2.3718127e+08 | BG35: =$BD35*H35 -> -12612927 | BH35: =$BD35*I35 -> 37359803 | BI35: =$BD35*J35 -> 51557206 | BJ35: =$BD35*K35 -> -23546434 | BK35: =$BD35*L35 -> 112945.17 | BL35: =$BD35*M35 -> 36251830 | BM35: =$BD35*N35 -> 7485518.4 | ... BV35: =$BD35*W35 -> 0
A36: FY_2024 | B36: 2024 Campaign | C36: 2024 | D36: 45474 | E36: =AVP!G36 -> 0.047482288 | F36: =AVP!F36 -> -161.93317 | G36: 2455.24 | H36: -140.13616 | I36: 416.27711 | J36: 765.1333 | K36: -256.99128 | L36: 0.17124917 | M36: 375.5408 | N36: 48.559183 | O36: 2.993724e-08 | P36: 1.8031148e-06 | Q36: 126.61589 | R36: -108.04891 | S36: -91.078063 | T36: -18.958915 | U36: 0 | V36: 0 | W36: 0 | BD36: 96091.605 | BF36: =$BD36*G36 -> 2.3592795e+08 | BG36: =$BD36*H36 -> -13465908 | BH36: =$BD36*I36 -> 40000735 | BI36: =$BD36*J36 -> 73522887 | BJ36: =$BD36*K36 -> -24694705 | BK36: =$BD36*L36 -> 16455.607 | BL36: =$BD36*M36 -> 36086319 | BM36: =$BD36*N36 -> 4666129.8 | ... BV36: =$BD36*W36 -> 0
A37: FY_2024 | B37: 2024 Campaign | C37: 2024 | D37: 45505 | E37: =AVP!G37 -> 0.011142576 | F37: =AVP!F37 -> 40.509614 | G37: 2449.2533 | H37: -57.595195 | I37: 393.39531 | J37: 690.2839 | K37: -155.06138 | L37: 0.022772859 | M37: 375.47228 | N37: 0.88250619 | O37: 2.8395308e-08 | P37: 5.315418e-07 | Q37: 129.3393 | R37: -109.85632 | S37: -31.445418 | T37: -89.630655 | U37: 0 | V37: 0 | W37: 0 | BD37: 95584.521 | BF37: =$BD37*G37 -> 2.341107e+08 | BG37: =$BD37*H37 -> -5505209.2 | BH37: =$BD37*I37 -> 37602503 | BI37: =$BD37*J37 -> 65980456 | BJ37: =$BD37*K37 -> -14821468 | BK37: =$BD37*L37 -> 2176.7328 | BL37: =$BD37*M37 -> 35889338 | BM37: =$BD37*N37 -> 84353.932 | ... BV37: =$BD37*W37 -> 0
A38: FY_2025 | B38: 2024 Campaign | C38: 2024 | D38: 45536 | E38: =AVP!G38 -> 0.024494454 | F38: =AVP!F38 -> 103.13841 | G38: 2444.9632 | H38: 0 | I38: 436.14917 | J38: 640.40914 | K38: -95.872775 | L38: 0 | M38: 375.34962 | N38: 0.0028087807 | O38: 2.7641688e-08 | P38: 2.1569365e-07 | Q38: 115.59984 | R38: -111.0964 | S38: -10.765847 | T38: -203.37505 | U38: 0 | V38: 0 | W38: 516.18183 | BD38: 95547.008 | BF38: =$BD38*G38 -> 2.3360892e+08 | BG38: =$BD38*H38 -> 0 | BH38: =$BD38*I38 -> 41672749 | BI38: =$BD38*J38 -> 61189178 | BJ38: =$BD38*K38 -> -9160356.8 | BK38: =$BD38*L38 -> 0 | BL38: =$BD38*M38 -> 35863533 | BM38: =$BD38*N38 -> 268.3706 | ... BV38: =$BD38*W38 -> 49319630
